Workbook
Name HAGH: 'تعداد براساس قیمت'!$C$2:$C$61
Name HAGH: 'حجم براساس قیمت'!$C$2:$C$61
Name HOGH: 'تعداد براساس قیمت'!$D$2:$D$61
Name HOGH: 'حجم براساس قیمت'!$D$2:$D$61
Name PRICE: 'تعداد براساس قیمت'!$B$2:$B$61
Name PRICE: 'حجم براساس قیمت'!$B$2:$B$61

Sheet DATA
A1: اریخ | C1: خرید | E1: فروش | H1: قیمت پایانی | I1: شاخص کل | J1: شاخص هم وزن | K1: شاخص گروهی سهام در آن قرار دارد
C2: حقیقی | D2: حقوقی | E2: حقیقی | F2: حقوقی | G2: 1 | H2: 44993 | I2: 343291.8 | J2: 107183 | K2: 307344
A3: اسفند | B3: تعداد | C3: 1105 | D3: 3 | E3: 131 | F3: 14 | G3: 2 | H3: 45474 | I3: 344115.1 | J3: 107731 | K3: 308350
A4: 24 | B4: حجم | C4: 942682 | D4: 625018 | E4: 759166 | F4: 808534 | G4: 3 | H4: 44514 | I4: 344487.6 | J4: 108598 | K4: 308676
C5: ( | D5: ( | E5: ( | F5: ( | G5: 4 | H5: 46186 | I5: 346870.7 | J5: 110243 | K5: 310939
C6: 60 | D6: 39 | E6: 48 | F6: 51 | G6: 5 | H6: 47709 | I6: 350322.6 | J6: 110906 | K6: 313621
C7: %) | D7: %) | E7: %) | F7: %) | G7: 6 | H7: 48024 | I7: 353996.7 | J7: 111891 | K7: 316589
B8: ارزش | C8: 57.082 B | D8: 37.847 B | E8: 45.97 B | F8: 48.959 B | G8: 7 | H8: 48090 | I8: 356721.1 | J8: 112856 | K8: 319403
B9: قیمت میانگین | C9: 60553 | D9: 60553 | E9: 60553 | F9: 60553 | G9: 8 | H9: 47193 | I9: 359365.5 | J9: 112604 | K9: 322177
B10: تغییر مالکیت حقوقی به حقیقی | D10: 183516 | G10: 9 | H10: 48133 | I10: 362259.3 | J10: 113581 | K10: 325130
G11: 10 | H11: 47628 | I11: 361088.4 | J11: 114298 | K11: 323956
A12: اسفند | B12: تعداد | C12: 2373 | D12: 9 | E12: 1326 | F12: 23 | G12: 11 | H12: 49789 | I12: 367632.1 | J12: 117166 | K12: 329446
A13: 21 | B13: حجم | C13: 3566000 | D13: 2072000 | E13: 3664000 | F13: 1974000 | G13: 12 | H13: 50347 | I13: 369729.9 | J13: 118170 | K13: 331300
C14: ( | D14: ( | E14: ( | F14: ( | G14: 13 | H14: 51032 | I14: 375547.7 | J14: 120359 | K14: 336666
C15: 63 | D15: 36 | E15: 64 | F15: 35 | G15: 14 | H15: 50410 | I15: 377012.6 | J15: 119970 | K15: 338692
C16: %) | D16: %) | E16: %) | F16: %) | G16: 15 | H16: 50352 | I16: 384099.6 | J16: 121488 | K16: 345555
B17: ارزش | C17: 227.523 B | D17: 131.82 B | E17: 233.779 B | F17: 125.563 B | G17: 16 | H17: 48388 | I17: 367334.2 | J17: 116690 | K17: 330541
B18: قیمت میانگین | C18: 63812.09 | D18: 63615.28 | E18: 63805.47 | F18: 63617.75 | G18: 17 | H18: 47514 | I18: 365815.5 | J18: 113151 | K18: 330356
B19: تغییر مالکیت حقوقی به حقیقی | D19: -98423 | G19: 18 | H19: 48464 | I19: 358843.2 | J19: 109600 | K19: 324457
G20: 19 | H20: 50887 | I20: 353807.7 | J20: 108173 | K20: 319959
A21: اسفند | B21: تعداد | C21: 804 | D21: 4 | E21: 46 | F21: 11 | G21: 20 | H21: 53431 | I21: 359807.4 | J21: 109974 | K21: 325417
A22: 20 | B22: حجم | C22: 538026 | D22: 1255000 | E22: 1203000 | F22: 590200 | H22: 55917 | I22: 375650.2 | J22: 114555 | K22: 339693
C23: ( | D23: ( | E23: ( | F23: ( | H23: 58008 | I23: 392038.4 | J23: 118924 | K23: 354585
C24: 30 | D24: 69 | E24: 67 | F24: 32 | H24: 59999 | I24: 395912.6 | J24: 120589 | K24: 357358
C25: %) | D25: %) | E25: %) | F25: %) | H25: 59782 | I25: 399445.3 | J25: 122016 | K25: 359900
B26: ارزش | C26: 35.725 B | D26: 83.332 B | E26: 79.868 B | F26: 39.189 B | H26: 59611 | I26: 409962.5 | J26: 126014 | K26: 368792
B27: قیمت میانگین | C27: 66400 | D27: 66400 | E27: 66400 | F27: 66400 | H27: 59067 | I27: 410694.5 | J27: 126787 | K27: 369328
B28: تغییر مالکیت حقوقی به حقیقی | D28: -664800 | H28: 58263 | I28: 409807.8 | J28: 128090 | K28: 367714
H29: 57087 | I29: 406008.9 | J29: 129420 | K29: 364084
A30: اسفند | B30: تعداد | C30: 985 | D30: 3 | E30: 7 | F30: 0 | H30: 58130 | I30: 411211.5 | J30: 131850 | K30: 368748
A31: 19 | B31: حجم | C31: 440541 | D31: 300000 | E31: 740541 | F31: 0 | H31: 57523 | I31: 417001.9 | J31: 135541 | K31: 374034
C32: ( | D32: ( | E32: ( | F32: ( | H32: 57811 | I32: 418312.5 | J32: 137333 | K32: 375156
C33: 59 | D33: 40 | E33: 100 | F33: 0 | H33: 56218 | I33: 420668 | J33: 138235 | K33: 376984
C34: %) | D34: %) | E34: %) | F34: %) | H34: 55971 | I34: 427139.4 | J34: 139961 | K34: 382257
B35: ارزش | C35: 30.183 B | D35: 20.554 B | E35: 50.737 B | F35: 0 | H35: 57916 | I35: 426184.9 | J35: 140201 | K35: 381219
B36: قیمت میانگین | C36: 68514 | D36: 68514 | E36: 68514 | F36: 0 | H36: 57099 | I36: 428217 | J36: 141862 | K36: 382988
B37: تغییر مالکیت حقوقی به حقیقی | D37: -300000 | H37: 57605 | I37: 438880.2 | J37: 145542 | K37: 392188
H38: 58602 | I38: 440199.1 | J38: 145049 | K38: 392272
A39: اسفند | B39: تعداد | C39: 1490 | D39: 7 | E39: 1630 | F39: 4 | H39: 57876 | I39: 445894.1 | J39: 146571 | K39: 396519
A40: 17 | B40: حجم | C40: 2082000 | D40: 1580000 | E40: 3042000 | F40: 621098 | H40: 58033 | I40: 452842.3 | J40: 147116 | K40: 402841
...

Sheet همبستگی و بتا
B1: بازدهی روزانه | C1: بازدهی روزانه شاخص کل | D1: بازدهی روزانه شاخص کل هم وزن | E1: بازدهی شاخص گروهی سهام در آن قرار دارد | F1: بازدهی تجمعی روزانه | G1: بازدهی تجمعی روزانه شاخص کل | H1: بازدهی تجمعی روزانه شاخص کل هم وزن | I1: بازدهی تجمعی شاخص گروهی سهام در آن قرار دارد | J1: ضریب همبستگی با شاخص کل (20 روز) | K1: ضریب همبستگی با شاخص کل هم وزن (20 روز) | L1: ضریب همبستگی با شاخص گروه (20 روز) | M1: ضریب بتا با شاخص کل (20 روز) | N1: ضریب بتا با شاخص کل هم وزن (20 روز) | O1: ضریب بتا با شاخص گروه (20 روز) | P1: ضریب آلفا با شاخص کل (20 روز) | Q1: ضریب آلفا با شاخص کل هم وزن (20 روز) | R1: ضریب آلفا با شاخص گروه (20 روز) | S1: نرخ رشد قیمت پایانی (5 روز) | T1: نرخ رشد قیمت پایانی (20 روز) | U1: نسبت بین نماد و شاخص کل هم وزن | V1: نسبت بین شاخص کل و شاخص کل هم وزن | W1: نسبت بین شاخص گروه و شاخص کل هم وزن | X1: یکه کردن نماد | Y1: یکه کردن شاخص کل | Z1: یکه کردن شاخص کل هم وزن | AA1: یکه کردن شاخص گروهی سهام در آن قرار دارد | AB1: =MAX(DATA!H2:K61) -> 555167.7
A2: 1 | B2: =(DATA!H3-DATA!H2)/DATA!H2 -> 0.010690552 | C2: =(DATA!I3-DATA!I2)/DATA!I2 -> 0.0023982513 | D2: =(DATA!J3-DATA!J2)/DATA!J2 -> 0.0051127511 | E2: =(DATA!K3-DATA!K2)/DATA!K2 -> 0.0032732053 | F2: 0 | G2: 0 | H2: 0 | I2: 0 | U2: =DATA!H2/DATA!J2 -> 0.41977739 | V2: =DATA!I2/DATA!J2 -> 3.2028568 | W2: =DATA!K2/DATA!J2 -> 2.8674697 | X2: =DATA!H2/$AB$1 -> 0.08104398 | Y2: =DATA!I2/$AB$1 -> 0.61835694 | Z2: =DATA!J2/$AB$1 -> 0.19306419 | AA2: =DATA!K2/$AB$1 -> 0.55360569
A3: 2 | B3: =(DATA!H4-DATA!H3)/DATA!H3 -> -0.021110965 | C3: =(DATA!I4-DATA!I3)/DATA!I3 -> 0.0010824866 | D3: =(DATA!J4-DATA!J3)/DATA!J3 -> 0.0080478228 | E3: =(DATA!K4-DATA!K3)/DATA!K3 -> 0.0010572401 | F3: =B2+F2 -> 0.010690552 | G3: =C2+G2 -> 0.0023982513 | H3: =D2+H2 -> 0.0051127511 | I3: =E2+I2 -> 0.0032732053 | U3: =DATA!H3/DATA!J3 -> 0.42210691 | V3: =DATA!I3/DATA!J3 -> 3.1942069 | W3: =DATA!K3/DATA!J3 -> 2.8622216 | X3: =DATA!H3/$AB$1 -> 0.081910385 | Y3: =DATA!I3/$AB$1 -> 0.61983992 | Z3: =DATA!J3/$AB$1 -> 0.19405127 | AA3: =DATA!K3/$AB$1 -> 0.55541776
A4: 3 | B4: =(DATA!H5-DATA!H4)/DATA!H4 -> 0.037561217 | C4: =(DATA!I5-DATA!I4)/DATA!I4 -> 0.0069178107 | D4: =(DATA!J5-DATA!J4)/DATA!J4 -> 0.015147609 | E4: =(DATA!K5-DATA!K4)/DATA!K4 -> 0.0073313118 | F4: =B3+F3 -> -0.010420413 | G4: =C3+G3 -> 0.0034807379 | H4: =D3+H3 -> 0.013160574 | I4: =E3+I3 -> 0.0043304454 | U4: =DATA!H4/DATA!J4 -> 0.40989705 | V4: =DATA!I4/DATA!J4 -> 3.1721358 | W4: =DATA!K4/DATA!J4 -> 2.8423728 | X4: =DATA!H4/$AB$1 -> 0.080181178 | Y4: =DATA!I4/$AB$1 -> 0.62051088 | Z4: =DATA!J4/$AB$1 -> 0.19561297 | AA4: =DATA!K4/$AB$1 -> 0.55600497
A5: 4 | B5: =(DATA!H6-DATA!H5)/DATA!H5 -> 0.03297536 | C5: =(DATA!I6-DATA!I5)/DATA!I5 -> 0.0099515468 | D5: =(DATA!J6-DATA!J5)/DATA!J5 -> 0.0060139873 | E5: =(DATA!K6-DATA!K5)/DATA!K5 -> 0.008625486 | F5: =B4+F4 -> 0.027140804 | G5: =C4+G4 -> 0.010398549 | H5: =D4+H4 -> 0.028308183 | I5: =E4+I4 -> 0.011661757 | U5: =DATA!H5/DATA!J5 -> 0.41894723 | V5: =DATA!I5/DATA!J5 -> 3.1464193 | W5: =DATA!K5/DATA!J5 -> 2.8204875 | X5: =DATA!H5/$AB$1 -> 0.08319288 | Y5: =DATA!I5/$AB$1 -> 0.62480346 | Z5: =DATA!J5/$AB$1 -> 0.19857603 | AA5: =DATA!K5/$AB$1 -> 0.56008122
A6: 5 | B6: =(DATA!H7-DATA!H6)/DATA!H6 -> 0.0066025278 | C6: =(DATA!I7-DATA!I6)/DATA!I6 -> 0.010487762 | D6: =(DATA!J7-DATA!J6)/DATA!J6 -> 0.0088813951 | E6: =(DATA!K7-DATA!K6)/DATA!K6 -> 0.009463652 | F6: =B5+F5 -> 0.060116165 | G6: =C5+G5 -> 0.020350095 | H6: =D5+H5 -> 0.03432217 | I6: =E5+I5 -> 0.020287243 | S6: =SLOPE(DATA!H2:H6,A2:A6)/AVERAGE(DATA!H2:H6) -> 0.013422115 | U6: =DATA!H6/DATA!J6 -> 0.4301751 | V6: =DATA!I6/DATA!J6 -> 3.1587344 | W6: =DATA!K6/DATA!J6 -> 2.8278091 | X6: =DATA!H6/$AB$1 -> 0.085936195 | Y6: =DATA!I6/$AB$1 -> 0.63102122 | Z6: =DATA!J6/$AB$1 -> 0.19977027 | AA6: =DATA!K6/$AB$1 -> 0.56491219
A7: 6 | B7: =(DATA!H8-DATA!H7)/DATA!H7 -> 0.0013743128 | C7: =(DATA!I8-DATA!I7)/DATA!I7 -> 0.0076961169 | D7: =(DATA!J8-DATA!J7)/DATA!J7 -> 0.0086244649 | E7: =(DATA!K8-DATA!K7)/DATA!K7 -> 0.0088884958 | F7: =B6+F6 -> 0.066718692 | G7: =C6+G6 -> 0.030837857 | H7: =D6+H6 -> 0.043203565 | I7: =E6+I6 -> 0.029750895 | S7: =SLOPE(DATA!H3:H7,A3:A7)/AVERAGE(DATA!H3:H7) -> 0.017884324 | U7: =DATA!H7/DATA!J7 -> 0.42920342 | V7: =DATA!I7/DATA!J7 -> 3.1637638 | W7: =DATA!K7/DATA!J7 -> 2.8294412 | X7: =DATA!H7/$AB$1 -> 0.086503592 | Y7: =DATA!I7/$AB$1 -> 0.63763922 | Z7: =DATA!J7/$AB$1 -> 0.20154451 | AA7: =DATA!K7/$AB$1 -> 0.57025832
A8: 7 | B8: =(DATA!H9-DATA!H8)/DATA!H8 -> -0.018652527 | C8: =(DATA!I9-DATA!I8)/DATA!I8 -> 0.0074130742 | D8: =(DATA!J9-DATA!J8)/DATA!J8 -> -0.002232934 | E8: =(DATA!K9-DATA!K8)/DATA!K8 -> 0.0086849529 | F8: =B7+F7 -> 0.068093005 | G8: =C7+G7 -> 0.038533974 | H8: =D7+H7 -> 0.05182803 | I8: =E7+I7 -> 0.038639391 | S8: =SLOPE(DATA!H4:H8,A4:A8)/AVERAGE(DATA!H4:H8) -> 0.019166564 | U8: =DATA!H8/DATA!J8 -> 0.42611824 | V8: =DATA!I8/DATA!J8 -> 3.1608519 | W8: =DATA!K8/DATA!J8 -> 2.8301818 | X8: =DATA!H8/$AB$1 -> 0.086622475 | Y8: =DATA!I8/$AB$1 -> 0.64254657 | Z8: =DATA!J8/$AB$1 -> 0.20328272 | AA8: =DATA!K8/$AB$1 -> 0.57532706
A9: 8 | B9: =(DATA!H10-DATA!H9)/DATA!H9 -> 0.019918208 | C9: =(DATA!I10-DATA!I9)/DATA!I9 -> 0.0080525259 | D9: =(DATA!J10-DATA!J9)/DATA!J9 -> 0.0086764236 | E9: =(DATA!K10-DATA!K9)/DATA!K9 -> 0.0091657691 | F9: =B8+F8 -> 0.049440479 | G9: =C8+G8 -> 0.045947048 | H9: =D8+H8 -> 0.049595096 | I9: =E8+I8 -> 0.047324344 | S9: =SLOPE(DATA!H5:H9,A5:A9)/AVERAGE(DATA!H5:H9) -> 0.0050484397 | U9: =DATA!H9/DATA!J9 -> 0.41910589 | V9: =DATA!I9/DATA!J9 -> 3.1914097 | W9: =DATA!K9/DATA!J9 -> 2.8611506 | X9: =DATA!H9/$AB$1 -> 0.085006747 | Y9: =DATA!I9/$AB$1 -> 0.64730981 | Z9: =DATA!J9/$AB$1 -> 0.2028288 | AA9: =DATA!K9/$AB$1 -> 0.58032375
A10: 9 | B10: =(DATA!H11-DATA!H10)/DATA!H10 -> -0.010491762 | C10: =(DATA!I11-DATA!I10)/DATA!I10 -> -0.0032322152 | D10: =(DATA!J11-DATA!J10)/DATA!J10 -> 0.0063126755 | E10: =(DATA!K11-DATA!K10)/DATA!K10 -> -0.0036108633 | F10: =B9+F9 -> 0.069358687 | G10: =C9+G9 -> 0.053999574 | H10: =D9+H9 -> 0.058271519 | I10: =E9+I9 -> 0.056490113 | S10: =SLOPE(DATA!H6:H10,A6:A10)/AVERAGE(DATA!H6:H10) -> 3.5542695e-05 | U10: =DATA!H10/DATA!J10 -> 0.42377686 | V10: =DATA!I10/DATA!J10 -> 3.1894357 | W10: =DATA!K10/DATA!J10 -> 2.8625386 | X10: =DATA!H10/$AB$1 -> 0.086699929 | Y10: =DATA!I10/$AB$1 -> 0.65252229 | Z10: =DATA!J10/$AB$1 -> 0.20458863 | AA10: =DATA!K10/$AB$1 -> 0.58564286
A11: 10 | B11: =(DATA!H12-DATA!H11)/DATA!H11 -> 0.04537247 | C11: =(DATA!I12-DATA!I11)/DATA!I11 -> 0.018122155 | D11: =(DATA!J12-DATA!J11)/DATA!J11 -> 0.025092303 | E11: =(DATA!K12-DATA!K11)/DATA!K11 -> 0.016946746 | F11: =B10+F10 -> 0.058866925 | G11: =C10+G10 -> 0.050767359 | H11: =D10+H10 -> 0.064584195 | I11: =E10+I10 -> 0.05287925 | S11: =SLOPE(DATA!H7:H11,A7:A11)/AVERAGE(DATA!H7:H11) -> -0.0015664999 | U11: =DATA!H11/DATA!J11 -> 0.4167002 | V11: =DATA!I11/DATA!J11 -> 3.1591839 | W11: =DATA!K11/DATA!J11 -> 2.8343103 | X11: =DATA!H11/$AB$1 -> 0.085790294 | Y11: =DATA!I11/$AB$1 -> 0.6504132 | Z11: =DATA!J11/$AB$1 -> 0.20588013 | AA11: =DATA!K11/$AB$1 -> 0.58352818
A12: 11 | B12: =(DATA!H13-DATA!H12)/DATA!H12 -> 0.011207295 | C12: =(DATA!I13-DATA!I12)/DATA!I12 -> 0.0057062482 | D12: =(DATA!J13-DATA!J12)/DATA!J12 -> 0.0085690388 | E12: =(DATA!K13-DATA!K12)/DATA!K12 -> 0.0056276294 | F12: =B11+F11 -> 0.10423939 | G12: =C11+G11 -> 0.068889514 | H12: =D11+H11 -> 0.089676497 | I12: =E11+I11 -> 0.069825996 | S12: =SLOPE(DATA!H8:H12,A8:A12)/AVERAGE(DATA!H8:H12) -> 0.0079577965 | U12: =DATA!H12/DATA!J12 -> 0.4249441 | V12: =DATA!I12/DATA!J12 -> 3.1377029 | W12: =DATA!K12/DATA!J12 -> 2.8117884 | X12: =DATA!H12/$AB$1 -> 0.089682811 | Y12: =DATA!I12/$AB$1 -> 0.66220009 | Z12: =DATA!J12/$AB$1 -> 0.21104614 | AA12: =DATA!K12/$AB$1 -> 0.59341709
A13: 12 | B13: =(DATA!H14-DATA!H13)/DATA!H13 -> 0.013605577 | C13: =(DATA!I14-DATA!I13)/DATA!I13 -> 0.015735271 | D13: =(DATA!J14-DATA!J13)/DATA!J13 -> 0.01852416 | E13: =(DATA!K14-DATA!K13)/DATA!K13 -> 0.0161968 | F13: =B12+F12 -> 0.11544669 | G13: =C12+G12 -> 0.074595762 | H13: =D12+H12 -> 0.098245536 | I13: =E12+I12 -> 0.075453625 | S13: =SLOPE(DATA!H9:H13,A9:A13)/AVERAGE(DATA!H9:H13) -> 0.016380764 | U13: =DATA!H13/DATA!J13 -> 0.42605568 | V13: =DATA!I13/DATA!J13 -> 3.1287966 | W13: =DATA!K13/DATA!J13 -> 2.8035881 | X13: =DATA!H13/$AB$1 -> 0.090687913 | Y13: =DATA!I13/$AB$1 -> 0.66597877 | Z13: =DATA!J13/$AB$1 -> 0.2128546 | AA13: =DATA!K13/$AB$1 -> 0.59675662
A14: 13 | B14: =(DATA!H15-DATA!H14)/DATA!H14 -> -0.012188431 | C14: =(DATA!I15-DATA!I14)/DATA!I14 -> 0.0039007029 | D14: =(DATA!J15-DATA!J14)/DATA!J14 -> -0.0032319976 | E14: =(DATA!K15-DATA!K14)/DATA!K14 -> 0.0060178337 | F14: =B13+F13 -> 0.12905227 | G14: =C13+G13 -> 0.090331033 | H14: =D13+H13 -> 0.1167697 | I14: =E13+I13 -> 0.091650425 | S14: =SLOPE(DATA!H10:H14,A10:A14)/AVERAGE(DATA!H10:H14) -> 0.017245848 | U14: =DATA!H14/DATA!J14 -> 0.42399821 | V14: =DATA!I14/DATA!J14 -> 3.1202295 | W14: =DATA!K14/DATA!J14 -> 2.7971818 | X14: =DATA!H14/$AB$1 -> 0.091921774 | Y14: =DATA!I14/$AB$1 -> 0.67645812 | Z14: =DATA!J14/$AB$1 -> 0.21679756 | AA14: =DATA!K14/$AB$1 -> 0.60642217
A15: 14 | B15: =(DATA!H16-DATA!H15)/DATA!H15 -> -0.0011505654 | C15: =(DATA!I16-DATA!I15)/DATA!I15 -> 0.01879778 | D15: =(DATA!J16-DATA!J15)/DATA!J15 -> 0.012653163 | E15: =(DATA!K16-DATA!K15)/DATA!K15 -> 0.020263248 | F15: =B14+F14 -> 0.11686384 | G15: =C14+G14 -> 0.094231736 | H15: =D14+H14 -> 0.1135377 | I15: =E14+I14 -> 0.097668259 | S15: =SLOPE(DATA!H11:H15,A11:A15)/AVERAGE(DATA!H11:H15) -> 0.013657376 | U15: =DATA!H15/DATA!J15 -> 0.42018838 | V15: =DATA!I15/DATA!J15 -> 3.1425573 | W15: =DATA!K15/DATA!J15 -> 2.8231391 | X15: =DATA!H15/$AB$1 -> 0.090801392 | Y15: =DATA!I15/$AB$1 -> 0.67909678 | Z15: =DATA!J15/$AB$1 -> 0.21609687 | AA15: =DATA!K15/$AB$1 -> 0.61007152
A16: 15 | B16: =(DATA!H17-DATA!H16)/DATA!H16 -> -0.039005402 | C16: =(DATA!I17-DATA!I16)/DATA!I16 -> -0.043648574 | D16: =(DATA!J17-DATA!J16)/DATA!J16 -> -0.039493613 | E16: =(DATA!K17-DATA!K16)/DATA!K16 -> -0.043448944 | F16: =B15+F15 -> 0.11571327 | G16: =C15+G15 -> 0.11302952 | H16: =D15+H15 -> 0.12619086 | I16: =E15+I15 -> 0.11793151 | S16: =SLOPE(DATA!H12:H16,A12:A16)/AVERAGE(DATA!H12:H16) -> 0.0023597825 | U16: =DATA!H16/DATA!J16 -> 0.41446069 | V16: =DATA!I16/DATA!J16 -> 3.1616258 | W16: =DATA!K16/DATA!J16 -> 2.844355 | X16: =DATA!H16/$AB$1 -> 0.090696919 | Y16: =DATA!I16/$AB$1 -> 0.6918623 | Z16: =DATA!J16/$AB$1 -> 0.21883117 | AA16: =DATA!K16/$AB$1 -> 0.62243355
A17: 16 | B17: =(DATA!H18-DATA!H17)/DATA!H17 -> -0.01806233 | C17: =(DATA!I18-DATA!I17)/DATA!I17 -> -0.0041343823 | D17: =(DATA!J18-DATA!J17)/DATA!J17 -> -0.03032822 | E17: =(DATA!K18-DATA!K17)/DATA!K17 -> -0.00055968851 | F17: =B16+F16 -> 0.076707868 | G17: =C16+G16 -> 0.069380942 | H17: =D16+H16 -> 0.086697249 | I17: =E16+I16 -> 0.074482563 | S17: =SLOPE(DATA!H13:H17,A13:A17)/AVERAGE(DATA!H13:H17) -> -0.0091765824 | U17: =DATA!H17/DATA!J17 -> 0.41467135 | V17: =DATA!I17/DATA!J17 -> 3.1479493 | W17: =DATA!K17/DATA!J17 -> 2.832642 | X17: =DATA!H17/$AB$1 -> 0.087159249 | Y17: =DATA!I17/$AB$1 -> 0.66166349 | Z17: =DATA!J17/$AB$1 -> 0.21018874 | AA17: =DATA!K17/$AB$1 -> 0.59538947
... A20: 19 | B20: =(DATA!H21-DATA!H20)/DATA!H20 -> 0.049993122 | C20: =(DATA!I21-DATA!I20)/DATA!I20 -> 0.016957517 | D20: =(DATA!J21-DATA!J20)/DATA!J20 -> 0.016649256 | E20: =(DATA!K21-DATA!K20)/DATA!K20 -> 0.017058436 | F20: =B19+F19 -> 0.12863552 | G20: =C19+G19 -> 0.03215436 | H20: =D19+H19 -> 0.011966114 | I20: =E19+I19 -> 0.042203218 | S20: =SLOPE(DATA!H16:H20,A16:A20)/AVERAGE(DATA!H16:H20) -> 0.0023330144 | U20: =DATA!H20/DATA!J20 -> 0.47042238 | V20: =DATA!I20/DATA!J20 -> 3.270758 | W20: =DATA!K20/DATA!J20 -> 2.9578453 | X20: =DATA!H20/$AB$1 -> 0.091660592 | Y20: =DATA!I20/$AB$1 -> 0.63729878 | Z20: =DATA!J20/$AB$1 -> 0.19484743 | AA20: =DATA!K20/$AB$1 -> 0.57632856
A21: 20 | B21: =(DATA!H22-DATA!H21)/DATA!H21 -> 0.046527297 | C21: =(DATA!I22-DATA!I21)/DATA!I21 -> 0.044031335 | D21: =(DATA!J22-DATA!J21)/DATA!J21 -> 0.0416553 | E21: =(DATA!K22-DATA!K21)/DATA!K21 -> 0.043869865 | F21: =B20+F20 -> 0.17862864 | G21: =C20+G20 -> 0.049111877 | H21: =D20+H20 -> 0.02861537 | I21: =E20+I20 -> 0.059261653 | J21: =CORREL(B2:B21,C2:C21) -> 0.49264293 | K21: =CORREL(B2:B21,D2:D21) -> 0.52571334 | L21: =CORREL(B2:B21,E2:E21) -> 0.46855035 | M21: =SLOPE(B2:B21,C2:C21) -> 0.75369198 | N21: =SLOPE(B2:B21,D2:D21) -> 0.71368051 | O21: =SLOPE(B2:B21,E2:E21) -> 0.72406987 | P21: =AVERAGE(B2:B21)-M21*AVERAGE(C2:C21) -> 0.0077477323 | Q21: =AVERAGE(B2:B21)-N21*AVERAGE(D2:D21) -> 0.0087502565 | R21: =AVERAGE(B2:B21)-O21*AVERAGE(E2:E21) -> 0.0075240756 | S21: =SLOPE(DATA!H17:H21,A17:A21)/AVERAGE(DATA!H17:H21) -> 0.027060446 | T21: =SLOPE(DATA!H2:H21,A2:A21)/AVERAGE(DATA!H2:H21) -> 0.006233839 | U21: =DATA!H21/DATA!J21 -> 0.4858512 | V21: =DATA!I21/DATA!J21 -> 3.2717497 | W21: =DATA!K21/DATA!J21 -> 2.9590358 | X21: =DATA!H21/$AB$1 -> 0.096242991 | Y21: =DATA!I21/$AB$1 -> 0.64810579 | Z21: =DATA!J21/$AB$1 -> 0.1980915 | AA21: =DATA!K21/$AB$1 -> 0.58615982
A22: 21 | B22: =(DATA!H23-DATA!H22)/DATA!H22 -> 0.03739471 | C22: =(DATA!I23-DATA!I22)/DATA!I22 -> 0.043626225 | D22: =(DATA!J23-DATA!J22)/DATA!J22 -> 0.038138885 | E22: =(DATA!K23-DATA!K22)/DATA!K22 -> 0.043839585 | F22: =B21+F21 -> 0.22515594 | G22: =C21+G21 -> 0.093143211 | H22: =D21+H21 -> 0.070270671 | I22: =E21+I21 -> 0.10313152 | J22: =CORREL(B3:B22,C3:C22) -> 0.52654108 | K22: =CORREL(B3:B22,D3:D22) -> 0.5567217 | L22: =CORREL(B3:B22,E3:E22) -> 0.50544827 | M22: =SLOPE(B3:B22,C3:C22) -> 0.73764953 | N22: =SLOPE(B3:B22,D3:D22) -> 0.71927365 | O22: =SLOPE(B3:B22,E3:E22) -> 0.71471425 | P22: =AVERAGE(B3:B22)-M22*AVERAGE(C3:C22) -> 0.0076370628 | Q22: =AVERAGE(B3:B22)-N22*AVERAGE(D3:D22) -> 0.0088780713 | R22: =AVERAGE(B3:B22)-O22*AVERAGE(E3:E22) -> 0.007457858 | S22: =SLOPE(DATA!H18:H22,A18:A22)/AVERAGE(DATA!H18:H22) -> 0.042490038 | T22: =SLOPE(DATA!H3:H22,A3:A22)/AVERAGE(DATA!H3:H22) -> 0.0072414523 | U22: =DATA!H22/DATA!J22 -> 0.48812361 | V22: =DATA!I22/DATA!J22 -> 3.2792126 | W22: =DATA!K22/DATA!J22 -> 2.9653267 | X22: =DATA!H22/$AB$1 -> 0.10072092 | Y22: =DATA!I22/$AB$1 -> 0.67664275 | Z22: =DATA!J22/$AB$1 -> 0.20634306 | AA22: =DATA!K22/$AB$1 -> 0.61187457
A23: 22 | B23: =(DATA!H24-DATA!H23)/DATA!H23 -> 0.034322852 | C23: =(DATA!I24-DATA!I23)/DATA!I23 -> 0.0098821952 | D23: =(DATA!J24-DATA!J23)/DATA!J23 -> 0.014000538 | E23: =(DATA!K24-DATA!K23)/DATA!K23 -> 0.0078204098 | F23: =B22+F22 -> 0.26255065 | G23: =C22+G22 -> 0.13676944 | H23: =D22+H22 -> 0.10840956 | I23: =E22+I22 -> 0.1469711 | J23: =CORREL(B4:B23,C4:C23) -> 0.5285555 | K23: =CORREL(B4:B23,D4:D23) -> 0.59723463 | L23: =CORREL(B4:B23,E4:E23) -> 0.50028424 | M23: =SLOPE(B4:B23,C4:C23) -> 0.71982559 | N23: =SLOPE(B4:B23,D4:D23) -> 0.74573652 | O23: =SLOPE(B4:B23,E4:E23) -> 0.68839252 | P23: =AVERAGE(B4:B23)-M23*AVERAGE(C4:C23) -> 0.010211792 | Q23: =AVERAGE(B4:B23)-N23*AVERAGE(D4:D23) -> 0.011291128 | R23: =AVERAGE(B4:B23)-O23*AVERAGE(E4:E23) -> 0.010185882 | S23: =SLOPE(DATA!H19:H23,A19:A23)/AVERAGE(DATA!H19:H23) -> 0.045214411 | T23: =SLOPE(DATA!H4:H23,A4:A23)/AVERAGE(DATA!H4:H23) -> 0.0086376548 | U23: =DATA!H23/DATA!J23 -> 0.4877737 | V23: =DATA!I23/DATA!J23 -> 3.2965457 | W23: =DATA!K23/DATA!J23 -> 2.9816101 | X23: =DATA!H23/$AB$1 -> 0.10448735 | Y23: =DATA!I23/$AB$1 -> 0.70616212 | Z23: =DATA!J23/$AB$1 -> 0.21421275 | AA23: =DATA!K23/$AB$1 -> 0.6386989
A24: 23 | B24: =(DATA!H25-DATA!H24)/DATA!H24 -> -0.0036167269 | C24: =(DATA!I25-DATA!I24)/DATA!I24 -> 0.0089229289 | D24: =(DATA!J25-DATA!J24)/DATA!J24 -> 0.011833583 | E24: =(DATA!K25-DATA!K24)/DATA!K24 -> 0.0071133149 | F24: =B23+F23 -> 0.2968735 | G24: =C23+G23 -> 0.14665163 | H24: =D23+H23 -> 0.12241009 | I24: =E23+I23 -> 0.15479151 | J24: =CORREL(B5:B24,C5:C24) -> 0.53035514 | K24: =CORREL(B5:B24,D5:D24) -> 0.57130299 | L24: =CORREL(B5:B24,E5:E24) -> 0.50567088 | M24: =SLOPE(B5:B24,C5:C24) -> 0.71615907 | N24: =SLOPE(B5:B24,D5:D24) -> 0.70971682 | O24: =SLOPE(B5:B24,E5:E24) -> 0.69004348 | P24: =AVERAGE(B5:B24)-M24*AVERAGE(C5:C24) -> 0.0081073426 | Q24: =AVERAGE(B5:B24)-N24*AVERAGE(D5:D24) -> 0.0095465883 | R24: =AVERAGE(B5:B24)-O24*AVERAGE(E5:E24) -> 0.0081220859 | S24: =SLOPE(DATA!H20:H24,A20:A24)/AVERAGE(DATA!H20:H24) -> 0.040973325 | T24: =SLOPE(DATA!H5:H24,A5:A24)/AVERAGE(DATA!H5:H24) -> 0.0098592936 | U24: =DATA!H24/DATA!J24 -> 0.49754953 | V24: =DATA!I24/DATA!J24 -> 3.2831568 | W24: =DATA!K24/DATA!J24 -> 2.9634378 | X24: =DATA!H24/$AB$1 -> 0.10807365 | Y24: =DATA!I24/$AB$1 -> 0.71314055 | Z24: =DATA!J24/$AB$1 -> 0.21721184 | AA24: =DATA!K24/$AB$1 -> 0.64369379
A25: 24 | B25: =(DATA!H26-DATA!H25)/DATA!H25 -> -0.0028603928 | C25: =(DATA!I26-DATA!I25)/DATA!I25 -> 0.026329512 | D25: =(DATA!J26-DATA!J25)/DATA!J25 -> 0.032766195 | E25: =(DATA!K26-DATA!K25)/DATA!K25 -> 0.024706863 | F25: =B24+F24 -> 0.29325677 | G25: =C24+G24 -> 0.15557456 | H25: =D24+H24 -> 0.13424368 | I25: =E24+I24 -> 0.16190483 | J25: =CORREL(B6:B25,C6:C25) -> 0.48782963 | K25: =CORREL(B6:B25,D6:D25) -> 0.51439827 | L25: =CORREL(B6:B25,E6:E25) -> 0.4712441 | M25: =SLOPE(B6:B25,C6:C25) -> 0.63867458 | N25: =SLOPE(B6:B25,D6:D25) -> 0.60884191 | O25: =SLOPE(B6:B25,E6:E25) -> 0.62581758 | P25: =AVERAGE(B6:B25)-M25*AVERAGE(C6:C25) -> 0.0063549898 | Q25: =AVERAGE(B6:B25)-N25*AVERAGE(D6:D25) -> 0.0074747191 | R25: =AVERAGE(B6:B25)-O25*AVERAGE(E6:E25) -> 0.0063095726 | S25: =SLOPE(DATA!H21:H25,A21:A25)/AVERAGE(DATA!H21:H25) -> 0.029226467 | T25: =SLOPE(DATA!H6:H25,A6:A25)/AVERAGE(DATA!H6:H25) -> 0.011064659 | U25: =DATA!H25/DATA!J25 -> 0.48995214 | V25: =DATA!I25/DATA!J25 -> 3.2737125 | W25: =DATA!K25/DATA!J25 -> 2.9496132 | X25: =DATA!H25/$AB$1 -> 0.10768278 | Y25: =DATA!I25/$AB$1 -> 0.71950385 | Z25: =DATA!J25/$AB$1 -> 0.21978224 | AA25: =DATA!K25/$AB$1 -> 0.64827259
A26: 25 | B26: =(DATA!H27-DATA!H26)/DATA!H26 -> -0.0091258325 | C26: =(DATA!I27-DATA!I26)/DATA!I26 -> 0.0017855292 | D26: =(DATA!J27-DATA!J26)/DATA!J26 -> 0.0061342391 | E26: =(DATA!K27-DATA!K26)/DATA!K26 -> 0.0014533938 | F26: =B25+F25 -> 0.29039638 | G26: =C25+G25 -> 0.18190407 | H26: =D25+H25 -> 0.16700987 | I26: =E25+I25 -> 0.18661169 | J26: =CORREL(B7:B26,C7:C26) -> 0.49318137 | K26: =CORREL(B7:B26,D7:D26) -> 0.50862855 | L26: =CORREL(B7:B26,E7:E26) -> 0.47725625 | M26: =SLOPE(B7:B26,C7:C26) -> 0.65413449 | N26: =SLOPE(B7:B26,D7:D26) -> 0.61129388 | O26: =SLOPE(B7:B26,E7:E26) -> 0.64150806 | P26: =AVERAGE(B7:B26)-M26*AVERAGE(C7:C26) -> 0.0057283129 | Q26: =AVERAGE(B7:B26)-N26*AVERAGE(D7:D26) -> 0.0067559998 | R26: =AVERAGE(B7:B26)-O26*AVERAGE(E7:E26) -> 0.0056496013 | S26: =SLOPE(DATA!H22:H26,A22:A26)/AVERAGE(DATA!H22:H26) -> 0.015617915 | T26: =SLOPE(DATA!H7:H26,A7:A26)/AVERAGE(DATA!H7:H26) -> 0.012280864 | U26: =DATA!H26/DATA!J26 -> 0.47305061 | V26: =DATA!I26/DATA!J26 -> 3.2533092 | W26: =DATA!K26/DATA!J26 -> 2.9265955 | X26: =DATA!H26/$AB$1 -> 0.10737476 | Y26: =DATA!I26/$AB$1 -> 0.73844804 | Z26: =DATA!J26/$AB$1 -> 0.22698367 | AA26: =DATA!K26/$AB$1 -> 0.66428937
A27: 26 | B27: =(DATA!H28-DATA!H27)/DATA!H27 -> -0.013611661 | C27: =(DATA!I28-DATA!I27)/DATA!I27 -> -0.0021590257 | D27: =(DATA!J28-DATA!J27)/DATA!J27 -> 0.010277079 | E27: =(DATA!K28-DATA!K27)/DATA!K27 -> -0.0043700992 | F27: =B26+F26 -> 0.28127055 | G27: =C26+G26 -> 0.1836896 | H27: =D26+H26 -> 0.17314411 | I27: =E26+I26 -> 0.18806508 | J27: =CORREL(B8:B27,C8:C27) -> 0.50403866 | K27: =CORREL(B8:B27,D8:D27) -> 0.49274181 | L27: =CORREL(B8:B27,E8:E27) -> 0.49367992 | M27: =SLOPE(B8:B27,C8:C27) -> 0.67684155 | N27: =SLOPE(B8:B27,D8:D27) -> 0.60288262 | O27: =SLOPE(B8:B27,E8:E27) -> 0.6694556 | P27: =AVERAGE(B8:B27)-M27*AVERAGE(C8:C27) -> 0.005138992 | Q27: =AVERAGE(B8:B27)-N27*AVERAGE(D8:D27) -> 0.0060115326 | R27: =AVERAGE(B8:B27)-O27*AVERAGE(E8:E27) -> 0.0051228801 | S27: =SLOPE(DATA!H23:H27,A23:A27)/AVERAGE(DATA!H23:H27) -> 0.002917694 | T27: =SLOPE(DATA!H8:H27,A8:A27)/AVERAGE(DATA!H8:H27) -> 0.013083995 | U27: =DATA!H27/DATA!J27 -> 0.46587584 | V27: =DATA!I27/DATA!J27 -> 3.2392477 | W27: =DATA!K27/DATA!J27 -> 2.91298 | X27: =DATA!H27/$AB$1 -> 0.10639488 | Y27: =DATA!I27/$AB$1 -> 0.73976656 | Z27: =DATA!J27/$AB$1 -> 0.22837604 | AA27: =DATA!K27/$AB$1 -> 0.66525484
A28: 27 | B28: =(DATA!H29-DATA!H28)/DATA!H28 -> -0.020184337 | C28: =(DATA!I29-DATA!I28)/DATA!I28 -> -0.0092699553 | D28: =(DATA!J29-DATA!J28)/DATA!J28 -> 0.010383324 | E28: =(DATA!K29-DATA!K28)/DATA!K28 -> -0.0098718025 | F28: =B27+F27 -> 0.26765889 | G28: =C27+G27 -> 0.18153058 | H28: =D27+H27 -> 0.18342119 | I28: =E27+I27 -> 0.18369499 | J28: =CORREL(B9:B28,C9:C28) -> 0.54245137 | K28: =CORREL(B9:B28,D9:D28) -> 0.46024372 | L28: =CORREL(B9:B28,E9:E28) -> 0.53726893 | M28: =SLOPE(B9:B28,C9:C28) -> 0.71879092 | N28: =SLOPE(B9:B28,D9:D28) -> 0.56718691 | O28: =SLOPE(B9:B28,E9:E28) -> 0.71784106 | P28: =AVERAGE(B9:B28)-M28*AVERAGE(C9:C28) -> 0.0053620511 | Q28: =AVERAGE(B9:B28)-N28*AVERAGE(D9:D28) -> 0.0058120188 | R28: =AVERAGE(B9:B28)-O28*AVERAGE(E9:E28) -> 0.0053614005 | S28: =SLOPE(DATA!H24:H28,A24:A28)/AVERAGE(DATA!H24:H28) -> -0.0070554256 | T28: =SLOPE(DATA!H9:H28,A9:A28)/AVERAGE(DATA!H9:H28) -> 0.01336859 | U28: =DATA!H28/DATA!J28 -> 0.45485986 | V28: =DATA!I28/DATA!J28 -> 3.1993739 | W28: =DATA!K28/DATA!J28 -> 2.8707471 | X28: =DATA!H28/$AB$1 -> 0.10494667 | Y28: =DATA!I28/$AB$1 -> 0.73816939 | Z28: =DATA!J28/$AB$1 -> 0.23072308 | AA28: =DATA!K28/$AB$1 -> 0.66234761
A29: 28 | B29: =(DATA!H30-DATA!H29)/DATA!H29 -> 0.018270359 | C29: =(DATA!I30-DATA!I29)/DATA!I29 -> 0.012814005 | D29: =(DATA!J30-DATA!J29)/DATA!J29 -> 0.018776078 | E29: =(DATA!K30-DATA!K29)/DATA!K29 -> 0.012810231 | F29: =B28+F28 -> 0.24747455 | G29: =C28+G28 -> 0.17226062 | H29: =D28+H28 -> 0.19380451 | I29: =E28+I28 -> 0.17382318 | J29: =CORREL(B10:B29,C10:C29) -> 0.54533447 | K29: =CORREL(B10:B29,D10:D29) -> 0.46495813 | L29: =CORREL(B10:B29,E10:E29) -> 0.53923996 | M29: =SLOPE(B10:B29,C10:C29) -> 0.72006264 | N29: =SLOPE(B10:B29,D10:D29) -> 0.56840473 | O29: =SLOPE(B10:B29,E10:E29) -> 0.71812501 | P29: =AVERAGE(B10:B29)-M29*AVERAGE(C10:C29) -> 0.0051001988 | Q29: =AVERAGE(B10:B29)-N29*AVERAGE(D10:D29) -> 0.0054338108 | R29: =AVERAGE(B10:B29)-O29*AVERAGE(E10:E29) -> 0.0051463532 | S29: =SLOPE(DATA!H25:H29,A25:A29)/AVERAGE(DATA!H25:H29) -> -0.011466594 | T29: =SLOPE(DATA!H10:H29,A10:A29)/AVERAGE(DATA!H10:H29) -> 0.012781847 | U29: =DATA!H29/DATA!J29 -> 0.44109875 | V29: =DATA!I29/DATA!J29 -> 3.1371419 | W29: =DATA!K29/DATA!J29 -> 2.8131973 | X29: =DATA!H29/$AB$1 -> 0.10282839 | Y29: =DATA!I29/$AB$1 -> 0.73132659 | Z29: =DATA!J29/$AB$1 -> 0.23311875 | AA29: =DATA!K29/$AB$1 -> 0.65580905
A30: 29 | B30: =(DATA!H31-DATA!H30)/DATA!H30 -> -0.010442113 | C30: =(DATA!I31-DATA!I30)/DATA!I30 -> 0.014081318 | D30: =(DATA!J31-DATA!J30)/DATA!J30 -> 0.027993932 | E30: =(DATA!K31-DATA!K30)/DATA!K30 -> 0.014334993 | F30: =B29+F29 -> 0.26574491 | G30: =C29+G29 -> 0.18507463 | H30: =D29+H29 -> 0.21258059 | I30: =E29+I29 -> 0.18663341 | J30: =CORREL(B11:B30,C11:C30) -> 0.51332673 | K30: =CORREL(B11:B30,D11:D30) -> 0.41716076 | L30: =CORREL(B11:B30,E11:E30) -> 0.50580246 | M30: =SLOPE(B11:B30,C11:C30) -> 0.68009103 | N30: =SLOPE(B11:B30,D11:D30) -> 0.49954834 | O30: =SLOPE(B11:B30,E11:E30) -> 0.67604982 | P30: =AVERAGE(B11:B30)-M30*AVERAGE(C11:C30) -> 0.0047759063 | Q30: =AVERAGE(B11:B30)-N30*AVERAGE(D11:D30) -> 0.0054260098 | R30: =AVERAGE(B11:B30)-O30*AVERAGE(E11:E30) -> 0.0048160112 | S30: =SLOPE(DATA!H26:H30,A26:A30)/AVERAGE(DATA!H26:H30) -> -0.0084577523 | T30: =SLOPE(DATA!H11:H30,A11:A30)/AVERAGE(DATA!H11:H30) -> 0.012481511 | U30: =DATA!H30/DATA!J30 -> 0.44087979 | V30: =DATA!I30/DATA!J30 -> 3.1187827 | W30: =DATA!K30/DATA!J30 -> 2.7967235 | X30: =DATA!H30/$AB$1 -> 0.1047071 | Y30: =DATA!I30/$AB$1 -> 0.74069781 | Z30: =DATA!J30/$AB$1 -> 0.23749581 | AA30: =DATA!K30/$AB$1 -> 0.66421011
A31: 30 | B31: =(DATA!H32-DATA!H31)/DATA!H31 -> 0.005006693 | C31: =(DATA!I32-DATA!I31)/DATA!I31 -> 0.0031429113 | D31: =(DATA!J32-DATA!J31)/DATA!J31 -> 0.013221092 | E31: =(DATA!K32-DATA!K31)/DATA!K31 -> 0.0029997273 | F31: =B30+F30 -> 0.2553028 | G31: =C30+G30 -> 0.19915594 | H31: =D30+H30 -> 0.24057452 | I31: =E30+I30 -> 0.20096841 | J31: =CORREL(B12:B31,C12:C31) -> 0.50384827 | K31: =CORREL(B12:B31,D12:D31) -> 0.38664344 | L31: =CORREL(B12:B31,E12:E31) -> 0.49926377 | M31: =SLOPE(B12:B31,C12:C31) -> 0.63895794 | N31: =SLOPE(B12:B31,D12:D31) -> 0.446063 | O31: =SLOPE(B12:B31,E12:E31) -> 0.63772537 | P31: =AVERAGE(B12:B31)-M31*AVERAGE(C12:C31) -> 0.0035413569 | Q31: =AVERAGE(B12:B31)-N31*AVERAGE(D12:D31) -> 0.0041431314 | R31: =AVERAGE(B12:B31)-O31*AVERAGE(E12:E31) -> 0.0035262125 | S31: =SLOPE(DATA!H27:H31,A27:A31)/AVERAGE(DATA!H27:H31) -> -0.0055521081 | T31: =SLOPE(DATA!H12:H31,A12:A31)/AVERAGE(DATA!H12:H31) -> 0.011603394 | U31: =DATA!H31/DATA!J31 -> 0.42439557 | V31: =DATA!I31/DATA!J31 -> 3.0765739 | W31: =DATA!K31/DATA!J31 -> 2.7595635 | X31: =DATA!H31/$AB$1 -> 0.10361374 | Y31: =DATA!I31/$AB$1 -> 0.75112781 | Z31: =DATA!J31/$AB$1 -> 0.24414425 | AA31: =DATA!K31/$AB$1 -> 0.67373156
A32: 31 | B32: =(DATA!H33-DATA!H32)/DATA!H32 -> -0.02755531 | C32: =(DATA!I33-DATA!I32)/DATA!I32 -> 0.0056309577 | D32: =(DATA!J33-DATA!J32)/DATA!J32 -> 0.0065679771 | E32: =(DATA!K33-DATA!K32)/DATA!K32 -> 0.0048726396 | F32: =B31+F31 -> 0.26030949 | G32: =C31+G31 -> 0.20229886 | H32: =D31+H31 -> 0.25379562 | I32: =E31+I31 -> 0.20396813 | J32: =CORREL(B13:B32,C13:C32) -> 0.48564256 | K32: =CORREL(B13:B32,D13:D32) -> 0.37433355 | L32: =CORREL(B13:B32,E13:E32) -> 0.48390137 | M32: =SLOPE(B13:B32,C13:C32) -> 0.64412106 | N32: =SLOPE(B13:B32,D13:D32) -> 0.4516188 | O32: =SLOPE(B13:B32,E13:E32) -> 0.64636962 | P32: =AVERAGE(B13:B32)-M32*AVERAGE(C13:C32) -> 0.0015712111 | Q32: =AVERAGE(B13:B32)-N32*AVERAGE(D13:D32) -> 0.0022045964 | R32: =AVERAGE(B13:B32)-O32*AVERAGE(E13:E32) -> 0.0015545045 | S32: =SLOPE(DATA!H28:H32,A28:A32)/AVERAGE(DATA!H28:H32) -> -0.00081021003 | T32: =SLOPE(DATA!H13:H32,A13:A32)/AVERAGE(DATA!H13:H32) -> 0.011187335 | U32: =DATA!H32/DATA!J32 -> 0.42095491 | V32: =DATA!I32/DATA!J32 -> 3.0459722 | W32: =DATA!K32/DATA!J32 -> 2.7317251 | X32: =DATA!H32/$AB$1 -> 0.1041325 | Y32: =DATA!I32/$AB$1 -> 0.75348854 | Z32: =DATA!J32/$AB$1 -> 0.2473721 | AA32: =DATA!K32/$AB$1 -> 0.67575257
... A60: 59 | B60: =(DATA!H61-DATA!H60)/DATA!H60 -> -0.05 | C60: =(DATA!I61-DATA!I60)/DATA!I60 -> -0.026994261 | D60: =(DATA!J61-DATA!J60)/DATA!J60 -> -0.013990164 | E60: =(DATA!K61-DATA!K60)/DATA!K60 -> -0.030042975 | F60: =B59+F59 -> 0.37130117 | G60: =C59+G59 -> 0.45211331 | H60: =D59+H59 -> 0.53415405 | I60: =E59+I59 -> 0.45694636 | J60: =CORREL(B41:B60,C41:C60) -> 0.0015502225 | K60: =CORREL(B41:B60,D41:D60) -> 0.038900367 | L60: =CORREL(B41:B60,E41:E60) -> 0.036333947 | M60: =SLOPE(B41:B60,C41:C60) -> 0.0026708722 | N60: =SLOPE(B41:B60,D41:D60) -> 0.078269006 | O60: =SLOPE(B41:B60,E41:E60) -> 0.061541523 | P60: =AVERAGE(B41:B60)-M60*AVERAGE(C41:C60) -> 0.00071332241 | Q60: =AVERAGE(B41:B60)-N60*AVERAGE(D41:D60) -> -2.9556329e-05 | R60: =AVERAGE(B41:B60)-O60*AVERAGE(E41:E60) -> 0.00028206204 | S60: =SLOPE(DATA!H56:H60,A56:A60)/AVERAGE(DATA!H56:H60) -> -0.0425835 | T60: =SLOPE(DATA!H41:H60,A41:A60)/AVERAGE(DATA!H41:H60) -> 0.0034532241 | U60: =DATA!H60/DATA!J60 -> 0.35221307 | V60: =DATA!I60/DATA!J60 -> 2.9528563 | W60: =DATA!K60/DATA!J60 -> 2.65649 | X60: =DATA!H60/$AB$1 -> 0.11481215 | Y60: =DATA!I60/$AB$1 -> 0.96255312 | Z60: =DATA!J60/$AB$1 -> 0.32597358 | AA60: =DATA!K60/$AB$1 -> 0.86594555
A61: 60 | F61: =B60+F60 -> 0.32130117 | G61: =C60+G60 -> 0.42511905 | H61: =D60+H60 -> 0.52016389 | I61: =E60+I60 -> 0.42690338 | S61: =SLOPE(DATA!H57:H61,A57:A61)/AVERAGE(DATA!H57:H61) -> -0.04401183 | T61: =SLOPE(DATA!H42:H61,A42:A61)/AVERAGE(DATA!H42:H61) -> -0.00084953338 | U61: =DATA!H61/DATA!J61 -> 0.33934998 | V61: =DATA!I61/DATA!J61 -> 2.9139122 | W61: =DATA!K61/DATA!J61 -> 2.6132408 | X61: =DATA!H61/$AB$1 -> 0.10907155 | Y61: =DATA!I61/$AB$1 -> 0.93656971 | Z61: =DATA!J61/$AB$1 -> 0.32141315 | AA61: =DATA!K61/$AB$1 -> 0.83992997

Sheet حجم
B1: Cell Num. | C1: حقیقی | D1: حقوقی | E1: میانگین حقیقی | F1: میانگین حقوقی | G1: حقیقی تجمعی | H1: حقوقی تجمعی | I1: حجم معاملات | J1: میانگین حجم معاملات | K1: ارزش معاملات | L1: میانگین ارزش معاملات
A2: 1 | B2: =B3+9 -> 535 | C2: =DATA!C535-DATA!E535 -> -1334000 | D2: =DATA!D535-DATA!F535 -> 1333502 | G2: =C2 -> -1334000 | H2: =D2 -> 1333502 | I2: =DATA!C535+DATA!D535 -> 4719000 | K2: =I2*H2 -> 6292795938000
A3: 2 | B3: =B4+9 -> 526 | C3: =DATA!C526-DATA!E526 -> -600000 | D3: =DATA!D526-DATA!F526 -> 600116 | G3: =G2+C3 -> -1934000 | H3: =H2+D3 -> 1933618 | I3: =DATA!C526+DATA!D526 -> 4284116 | K3: =I3*H3 -> 8283843811688
A4: 3 | B4: =B5+9 -> 517 | C4: =DATA!C517-DATA!E517 -> -2114000 | D4: =DATA!D517-DATA!F517 -> 2112848 | G4: =G3+C4 -> -4048000 | H4: =H3+D4 -> 4046466 | I4: =DATA!C517+DATA!D517 -> 4306000 | K4: =I4*H4 -> 17424082596000
A5: 4 | B5: =B6+9 -> 508 | C5: =DATA!C508-DATA!E508 -> -782000 | D5: =DATA!D508-DATA!F508 -> 782738 | G5: =G4+C5 -> -4830000 | H5: =H4+D5 -> 4829204 | I5: =DATA!C508+DATA!D508 -> 4826000 | K5: =I5*H5 -> 23305738504000
A6: 5 | B6: =B7+9 -> 499 | C6: =DATA!C499-DATA!E499 -> 134000 | D6: =DATA!D499-DATA!F499 -> -134189 | G6: =G5+C6 -> -4696000 | H6: =H5+D6 -> 4695015 | I6: =DATA!C499+DATA!D499 -> 2589428 | K6: =I6*H6 -> 12157403301420
A7: 6 | B7: =B8+9 -> 490 | C7: =DATA!C490-DATA!E490 -> -1221000 | D7: =DATA!D490-DATA!F490 -> 1220923 | G7: =G6+C7 -> -5917000 | H7: =H6+D7 -> 5915938 | I7: =DATA!C490+DATA!D490 -> 4030000 | K7: =I7*H7 -> 23841230140000
A8: 7 | B8: =B9+9 -> 481 | C8: =DATA!C481-DATA!E481 -> -154000 | D8: =DATA!D481-DATA!F481 -> 154501 | G8: =G7+C8 -> -6071000 | H8: =H7+D8 -> 6070439 | I8: =DATA!C481+DATA!D481 -> 2407607 | K8: =I8*H8 -> 14615231429473
A9: 8 | B9: =B10+9 -> 472 | C9: =DATA!C472-DATA!E472 -> -278000 | D9: =DATA!D472-DATA!F472 -> 278008 | G9: =G8+C9 -> -6349000 | H9: =H8+D9 -> 6348447 | I9: =DATA!C472+DATA!D472 -> 2218822 | K9: =I9*H9 -> 14086073869434
A10: 9 | B10: =B11+9 -> 463 | C10: =DATA!C463-DATA!E463 -> 265000 | D10: =DATA!D463-DATA!F463 -> -264654 | G10: =G9+C10 -> -6084000 | H10: =H9+D10 -> 6083793 | I10: =DATA!C463+DATA!D463 -> 2329062 | K10: =I10*H10 -> 14169531092166
A11: 10 | B11: =B12+9 -> 454 | C11: =DATA!C454-DATA!E454 -> -769000 | D11: =DATA!D454-DATA!F454 -> 769172 | G11: =G10+C11 -> -6853000 | H11: =H10+D11 -> 6852965 | I11: =DATA!C454+DATA!D454 -> 3442000 | K11: =I11*H11 -> 23587905530000
A12: 11 | B12: =B13+9 -> 445 | C12: =DATA!C445-DATA!E445 -> -1190000 | D12: =DATA!D445-DATA!F445 -> 1190000 | G12: =G11+C12 -> -8043000 | H12: =H11+D12 -> 8042965 | I12: =DATA!C445+DATA!D445 -> 7547000 | K12: =I12*H12 -> 60700256855000
A13: 12 | B13: =B14+9 -> 436 | C13: =DATA!C436-DATA!E436 -> -583000 | D13: =DATA!D436-DATA!F436 -> 582800 | G13: =G12+C13 -> -8626000 | H13: =H12+D13 -> 8625765 | I13: =DATA!C436+DATA!D436 -> 2755810 | K13: =I13*H13 -> 23770969444650
A14: 13 | B14: =B15+9 -> 427 | C14: =DATA!C427-DATA!E427 -> -932000 | D14: =DATA!D427-DATA!F427 -> 931566 | G14: =G13+C14 -> -9558000 | H14: =H13+D14 -> 9557331 | I14: =DATA!C427+DATA!D427 -> 2665000 | K14: =I14*H14 -> 25470287115000
A15: 14 | B15: =B16+9 -> 418 | C15: =DATA!C418-DATA!E418 -> -9114000 | D15: =DATA!D418-DATA!F418 -> 9115000 | G15: =G14+C15 -> -18672000 | H15: =H14+D15 -> 18672331 | I15: =DATA!C418+DATA!D418 -> 14413000 | K15: =I15*H15 -> 269124306703000
A16: 15 | B16: =B17+9 -> 409 | C16: =DATA!C409-DATA!E409 -> -6591000 | D16: =DATA!D409-DATA!F409 -> 6591000 | G16: =G15+C16 -> -25263000 | H16: =H15+D16 -> 25263331 | I16: =DATA!C409+DATA!D409 -> 11516000 | K16: =I16*H16 -> 290932519796000
A17: 16 | B17: =B18+9 -> 400 | C17: =DATA!C400-DATA!E400 -> -5064000 | D17: =DATA!D400-DATA!F400 -> 5064168 | G17: =G16+C17 -> -30327000 | H17: =H16+D17 -> 30327499 | I17: =DATA!C400+DATA!D5400 -> 2291000 | K17: =I17*H17 -> 69480300209000
A18: 17 | B18: =B19+9 -> 391 | C18: =DATA!C391-DATA!E391 -> -2475000 | D18: =DATA!D391-DATA!F391 -> 2474000 | G18: =G17+C18 -> -32802000 | H18: =H17+D18 -> 32801499 | I18: =DATA!C391+DATA!D391 -> 9387000 | K18: =I18*H18 -> 307907671113000
A19: 18 | B19: =B20+9 -> 382 | C19: =DATA!C382-DATA!E382 -> 176933 | D19: =DATA!D382-DATA!F382 -> -176933 | G19: =G18+C19 -> -32625067 | H19: =H18+D19 -> 32624566 | I19: =DATA!C382+DATA!D382 -> 220544 | K19: =I19*H19 -> 7195152283904
A20: 19 | B20: =B21+9 -> 373 | C20: =DATA!C373-DATA!E373 -> 260803 | D20: =DATA!D373-DATA!F373 -> -260803 | G20: =G19+C20 -> -32364264 | H20: =H19+D20 -> 32363763 | I20: =DATA!C373+DATA!D373 -> 447477 | K20: =I20*H20 -> 14482039575951
A21: 20 | B21: =B22+9 -> 364 | C21: =DATA!C364-DATA!E364 -> 1229341 | D21: =DATA!D364-DATA!F364 -> -1229000 | E21: =AVERAGE(C2:C21) -> -1556746.1 | F21: =AVERAGE(D2:D21) -> 1556738.1 | G21: =G20+C21 -> -31134923 | H21: =H20+D21 -> 31134763 | I21: =DATA!C364+DATA!D364 -> 1821000 | J21: =AVERAGE(I2:I21) -> 4410793.3 | K21: =I21*H21 -> 56696403423000 | L21: =AVERAGE(K2:K21) -> 6.4176187e+13
A22: 21 | B22: 355 | C22: =DATA!C355-DATA!E355 -> 4245000 | D22: =DATA!D355-DATA!F355 -> -4245000 | E22: =AVERAGE(C3:C22) -> -1277796.1 | F22: =AVERAGE(D3:D22) -> 1277813.1 | G22: =G21+C22 -> -26889923 | H22: =H21+D22 -> 26889763 | I22: =DATA!C355+DATA!D355 -> 13180000 | J22: =AVERAGE(I3:I22) -> 4833843.3 | K22: =I22*H22 -> 354407076340000 | L22: =AVERAGE(K3:K22) -> 8.1581901e+13
A23: 22 | B23: 346 | C23: =DATA!C346-DATA!E346 -> -379000 | D23: =DATA!D346-DATA!F346 -> 379000 | E23: =AVERAGE(C4:C23) -> -1266746.1 | F23: =AVERAGE(D4:D23) -> 1266757.2 | G23: =G22+C23 -> -27268923 | H23: =H22+D23 -> 27268763 | I23: =DATA!C346+DATA!D346 -> 6859000 | J23: =AVERAGE(I4:I23) -> 4962587.5 | K23: =I23*H23 -> 187036445417000 | L23: =AVERAGE(K4:K23) -> 9.0519531e+13
A24: 23 | B24: 337 | C24: =DATA!C337-DATA!E337 -> 735000 | D24: =DATA!D337-DATA!F337 -> -735000 | E24: =AVERAGE(C5:C24) -> -1124296.1 | F24: =AVERAGE(D5:D24) -> 1124364.9 | G24: =G23+C24 -> -26533923 | H24: =H23+D24 -> 26533763 | I24: =DATA!C337+DATA!D337 -> 9395000 | J24: =AVERAGE(I5:I24) -> 5217037.5 | K24: =I24*H24 -> 249284703385000 | L24: =AVERAGE(K5:K24) -> 1.0211256e+14
A25: 24 | B25: 328 | C25: =DATA!C328-DATA!E328 -> -853000 | D25: =DATA!D328-DATA!F328 -> 853000 | E25: =AVERAGE(C6:C25) -> -1127846.1 | F25: =AVERAGE(D6:D25) -> 1127877.9 | G25: =G24+C25 -> -27386923 | H25: =H24+D25 -> 27386763 | I25: =DATA!C328+DATA!D328 -> 4376000 | J25: =AVERAGE(I6:I25) -> 5194537.5 | K25: =I25*H25 -> 119844474888000 | L25: =AVERAGE(K6:K25) -> 1.069395e+14
A26: 25 | B26: 319 | C26: =DATA!C319-DATA!E319 -> -1618000 | D26: =DATA!D319-DATA!F319 -> 1619000 | E26: =AVERAGE(C7:C26) -> -1215446.1 | F26: =AVERAGE(D7:D26) -> 1215537.4 | G26: =G25+C26 -> -29004923 | H26: =H25+D26 -> 29005763 | I26: =DATA!C319+DATA!D319 -> 8617000 | J26: =AVERAGE(I7:I26) -> 5495916.1 | K26: =I26*H26 -> 249942659771000 | L26: =AVERAGE(K7:K26) -> 1.1882876e+14
A27: 26 | B27: 310 | C27: =DATA!C310-DATA!E310 -> -2335000 | D27: =DATA!D310-DATA!F310 -> 2335000 | E27: =AVERAGE(C8:C27) -> -1271146.1 | F27: =AVERAGE(D8:D27) -> 1271241.2 | G27: =G26+C27 -> -31339923 | H27: =H26+D27 -> 31340763 | I27: =DATA!C310+DATA!D310 -> 9826000 | J27: =AVERAGE(I8:I27) -> 5785716.1 | K27: =I27*H27 -> 307954337238000 | L27: =AVERAGE(K8:K27) -> 1.3303442e+14
A28: 27 | B28: 301 | C28: =DATA!C301-DATA!E301 -> -162000 | D28: =DATA!D301-DATA!F301 -> 162000 | E28: =AVERAGE(C9:C28) -> -1271546.1 | F28: =AVERAGE(D9:D28) -> 1271616.2 | G28: =G27+C28 -> -31501923 | H28: =H27+D28 -> 31502763 | I28: =DATA!C301+DATA!D301 -> 3911000 | J28: =AVERAGE(I9:I28) -> 5860885.8 | K28: =I28*H28 -> 123207306093000 | L28: =AVERAGE(K9:K28) -> 1.3846402e+14
A29: 28 | B29: 292 | C29: =DATA!C292-DATA!E292 -> 72000 | D29: =DATA!D292-DATA!F292 -> -71682 | E29: =AVERAGE(C10:C29) -> -1254046.1 | F29: =AVERAGE(D10:D29) -> 1254131.7 | G29: =G28+C29 -> -31429923 | H29: =H28+D29 -> 31431081 | I29: =DATA!C292+DATA!D292 -> 3627321 | J29: =AVERAGE(I10:I29) -> 5931310.7 | K29: =I29*H29 -> 114010620164001 | L29: =AVERAGE(K10:K29) -> 1.4346025e+14
A30: 29 | B30: 283 | C30: =DATA!C283-DATA!E283 -> 1500000 | D30: =DATA!D283-DATA!F283 -> -1500602 | E30: =AVERAGE(C11:C30) -> -1192296.1 | F30: =AVERAGE(D11:D30) -> 1192334.3 | G30: =G29+C30 -> -29929923 | H30: =H29+D30 -> 29930479 | I30: =DATA!C283+DATA!D283 -> 3971398 | J30: =AVERAGE(I11:I30) -> 6013427.5 | K30: =I30*H30 -> 118865844439642 | L30: =AVERAGE(K11:K30) -> 1.4869506e+14
A31: 30 | B31: 274 | C31: =DATA!C274-DATA!E274 -> -240000 | D31: =DATA!D274-DATA!F274 -> 240349 | E31: =AVERAGE(C12:C31) -> -1165846.1 | F31: =AVERAGE(D12:D31) -> 1165893.1 | G31: =G30+C31 -> -30169923 | H31: =H30+D31 -> 30170828 | I31: =DATA!C274+DATA!D274 -> 2514445 | J31: =AVERAGE(I12:I31) -> 5967049.8 | K31: =I31*H31 -> 75862887610460 | L31: =AVERAGE(K12:K31) -> 1.5130881e+14
A32: 31 | B32: 265 | C32: =DATA!C265-DATA!E265 -> 889123 | D32: =DATA!D265-DATA!F265 -> -889139 | E32: =AVERAGE(C13:C32) -> -1061890 | F32: =AVERAGE(D13:D32) -> 1061936.2 | G32: =G31+C32 -> -29280800 | H32: =H31+D32 -> 29281689 | I32: =DATA!C265+DATA!D265 -> 2606861 | J32: =AVERAGE(I13:I32) -> 5720042.8 | K32: =I32*H32 -> 76333293068229 | L32: =AVERAGE(K13:K32) -> 1.5209046e+14
A33: 32 | B33: 256 | C33: =DATA!C256-DATA!E256 -> -283000 | D33: =DATA!D256-DATA!F256 -> 283151 | E33: =AVERAGE(C14:C33) -> -1046890 | F33: =AVERAGE(D14:D33) -> 1046953.8 | G33: =G32+C33 -> -29563800 | H33: =H32+D33 -> 29564840 | I33: =DATA!C256+DATA!D256 -> 2553083 | J33: =AVERAGE(I14:I33) -> 5709906.5 | K33: =I33*H33 -> 75481490401720 | L33: =AVERAGE(K14:K33) -> 1.5467599e+14
A34: 33 | B34: 247 | C34: =DATA!C247-DATA!E247 -> 45000 | D34: =DATA!D247-DATA!F247 -> -45047 | E34: =AVERAGE(C15:C34) -> -998040 | F34: =AVERAGE(D15:D34) -> 998123.1 | G34: =G33+C34 -> -29518800 | H34: =H33+D34 -> 29519793 | I34: =DATA!C247+DATA!D247 -> 1546055 | J34: =AVERAGE(I15:I34) -> 5653959.2 | K34: =I34*H34 -> 45639223566615 | L34: =AVERAGE(K15:K34) -> 1.5568444e+14
A35: 34 | B35: 238 | C35: =DATA!C238-DATA!E238 -> -85000 | D35: =DATA!D238-DATA!F238 -> 84966 | E35: =AVERAGE(C16:C35) -> -546590 | F35: =AVERAGE(D16:D35) -> 546621.4 | G35: =G34+C35 -> -29603800 | H35: =H34+D35 -> 29604759 | I35: =DATA!C238+DATA!D238 -> 1624500 | J35: =AVERAGE(I16:I35) -> 5014534.2 | K35: =I35*H35 -> 48092930995500 | L35: =AVERAGE(K16:K35) -> 1.4463287e+14
A36: 35 | B36: 229 | C36: =DATA!C229-DATA!E229 -> -256000 | D36: =DATA!D229-DATA!F229 -> 255280 | E36: =AVERAGE(C17:C36) -> -229840 | F36: =AVERAGE(D17:D36) -> 229835.4 | G36: =G35+C36 -> -29859800 | H36: =H35+D36 -> 29860039 | I36: =DATA!C229+DATA!D229 -> 2123280 | J36: =AVERAGE(I17:I36) -> 4544898.2 | K36: =I36*H36 -> 63401223607920 | L36: =AVERAGE(K17:K36) -> 1.332563e+14
A37: 36 | B37: 220 | C37: =DATA!C220-DATA!E220 -> -49000 | D37: =DATA!D220-DATA!F220 -> 49612 | E37: =AVERAGE(C18:C37) -> 20910 | F37: =AVERAGE(D18:D37) -> -20892.4 | G37: =G36+C37 -> -29908800 | H37: =H36+D37 -> 29909651 | I37: =DATA!C220+DATA!D220 -> 1553673 | J37: =AVERAGE(I18:I37) -> 4508031.8 | K37: =I37*H37 -> 46469817198123 | L37: =AVERAGE(K18:K37) -> 1.3210578e+14
A38: 37 | B38: 211 | C38: =DATA!C211-DATA!E211 -> -310000 | D38: =DATA!D211-DATA!F211 -> 309695 | E38: =AVERAGE(C19:C38) -> 129160 | F38: =AVERAGE(D19:D38) -> -129107.65 | G38: =G37+C38 -> -30218800 | H38: =H37+D38 -> 30219346 | I38: =DATA!C211+DATA!D211 -> 2281782 | J38: =AVERAGE(I19:I38) -> 4152771 | K38: =I38*H38 -> 68953959754572 | L38: =AVERAGE(K19:K38) -> 1.2015809e+14
A39: 38 | B39: 202 | C39: =DATA!C202-DATA!E202 -> -854000 | D39: =DATA!D202-DATA!F202 -> 854509 | E39: =AVERAGE(C20:C39) -> 77613.35 | F39: =AVERAGE(D20:D39) -> -77535.55 | G39: =G38+C39 -> -31072800 | H39: =H38+D39 -> 31073855 | I39: =DATA!C202+DATA!D202 -> 2318000 | J39: =AVERAGE(I20:I39) -> 4257643.8 | K39: =I39*H39 -> 72029195890000 | L39: =AVERAGE(K20:K39) -> 1.233998e+14
A40: 39 | B40: 193 | C40: =DATA!C193-DATA!E193 -> 30000 | D40: =DATA!D193-DATA!F193 -> -30000 | E40: =AVERAGE(C21:C40) -> 66073.2 | F40: =AVERAGE(D21:D40) -> -65995.4 | G40: =G39+C40 -> -31042800 | H40: =H39+D40 -> 31043855 | I40: =DATA!C193+DATA!D193 -> 2840000 | J40: =AVERAGE(I21:I40) -> 4377269.9 | K40: =I40*H40 -> 88164548200000 | L40: =AVERAGE(K21:K40) -> 1.2708392e+14
...

Sheet تعداد
B1: Cell Num. | C1: حقیقی | D1: حقوقی | E1: میانگین حقیقی | F1: میانگین حقوقی | G1: حقیقی تجمعی | H1: حقوقی تجمعی
A2: 1 | B2: 534 | C2: =DATA!C534-DATA!E534 -> -1491 | D2: =DATA!D534-DATA!F534 -> -2 | G2: =C2 -> -1491 | H2: =D2 -> -2
A3: 2 | B3: =B2-9 -> 525 | C3: =DATA!C525-DATA!E525 -> -185 | D3: =DATA!D525-DATA!F525 -> 10 | G3: =G2+C3 -> -1676 | H3: =H2+D3 -> 8
A4: 3 | B4: =B3-9 -> 516 | C4: =DATA!C516-DATA!E516 -> -1350 | D4: =DATA!D516-DATA!F516 -> 7 | G4: =G3+C4 -> -3026 | H4: =H3+D4 -> 15
A5: 4 | B5: =B4-9 -> 507 | C5: =DATA!C507-DATA!E507 -> -1316 | D5: =DATA!D507-DATA!F507 -> -2 | G5: =G4+C5 -> -4342 | H5: =H4+D5 -> 13
A6: 5 | B6: =B5-9 -> 498 | C6: =DATA!C498-DATA!E498 -> -299 | D6: =DATA!D498-DATA!F498 -> 1 | G6: =G5+C6 -> -4641 | H6: =H5+D6 -> 14
A7: 6 | B7: =B6-9 -> 489 | C7: =DATA!C489-DATA!E489 -> -192 | D7: =DATA!D489-DATA!F489 -> 0 | G7: =G6+C7 -> -4833 | H7: =H6+D7 -> 14
A8: 7 | B8: =B7-9 -> 480 | C8: =DATA!C480-DATA!E480 -> -205 | D8: =DATA!D480-DATA!F480 -> -1 | G8: =G7+C8 -> -5038 | H8: =H7+D8 -> 13
A9: 8 | B9: =B8-9 -> 471 | C9: =DATA!C471-DATA!E471 -> -365 | D9: =DATA!D471-DATA!F471 -> -1 | G9: =G8+C9 -> -5403 | H9: =H8+D9 -> 12
A10: 9 | B10: =B9-9 -> 462 | C10: =DATA!C462-DATA!E462 -> -17 | D10: =DATA!D462-DATA!F462 -> -4 | G10: =G9+C10 -> -5420 | H10: =H9+D10 -> 8
A11: 10 | B11: =B10-9 -> 453 | C11: =DATA!C453-DATA!E453 -> -403 | D11: =DATA!D453-DATA!F453 -> 8 | G11: =G10+C11 -> -5823 | H11: =H10+D11 -> 16
A12: 11 | B12: =B11-9 -> 444 | C12: =DATA!C444-DATA!E444 -> -1273 | D12: =DATA!D444-DATA!F444 -> -1 | G12: =G11+C12 -> -7096 | H12: =H11+D12 -> 15
A13: 12 | B13: =B12-9 -> 435 | C13: =DATA!C435-DATA!E435 -> 99 | D13: =DATA!D435-DATA!F435 -> 2 | G13: =G12+C13 -> -6997 | H13: =H12+D13 -> 17
A14: 13 | B14: =B13-9 -> 426 | C14: =DATA!C426-DATA!E426 -> -134 | D14: =DATA!D426-DATA!F426 -> 3 | G14: =G13+C14 -> -7131 | H14: =H13+D14 -> 20
A15: 14 | B15: =B14-9 -> 417 | C15: =DATA!C417-DATA!E417 -> -447 | D15: =DATA!D417-DATA!F417 -> 7 | G15: =G14+C15 -> -7578 | H15: =H14+D15 -> 27
A16: 15 | B16: =B15-9 -> 408 | C16: =DATA!C408-DATA!E408 -> -1014 | D16: =DATA!D408-DATA!F408 -> 5 | G16: =G15+C16 -> -8592 | H16: =H15+D16 -> 32
A17: 16 | B17: =B16-9 -> 399 | C17: =DATA!C399-DATA!E399 -> -686 | D17: =DATA!D399-DATA!F399 -> 1 | G17: =G16+C17 -> -9278 | H17: =H16+D17 -> 33
A18: 17 | B18: =B17-9 -> 390 | C18: =DATA!C390-DATA!E390 -> -1882 | D18: =DATA!D390-DATA!F390 -> 0 | G18: =G17+C18 -> -11160 | H18: =H17+D18 -> 33
A19: 18 | B19: =B18-9 -> 381 | C19: =DATA!C381-DATA!E381 -> -111 | D19: =DATA!D381-DATA!F381 -> -1 | G19: =G18+C19 -> -11271 | H19: =H18+D19 -> 32
A20: 19 | B20: =B19-9 -> 372 | C20: =DATA!C372-DATA!E372 -> -233 | D20: =DATA!D372-DATA!F372 -> -1 | G20: =G19+C20 -> -11504 | H20: =H19+D20 -> 31
A21: 20 | B21: =B20-9 -> 363 | C21: =DATA!C363-DATA!E363 -> -435 | D21: =DATA!D363-DATA!F363 -> -1 | E21: =AVERAGE(C2:C21) -> -596.95 | F21: =AVERAGE(D2:D21) -> 1.5 | G21: =G20+C21 -> -11939 | H21: =H20+D21 -> 30
A22: 21 | B22: =B21-9 -> 354 | C22: =DATA!C354-DATA!E354 -> 136 | D22: =DATA!D354-DATA!F354 -> -5 | E22: =AVERAGE(C3:C22) -> -515.6 | F22: =AVERAGE(D3:D22) -> 1.35 | G22: =G21+C22 -> -11803 | H22: =H21+D22 -> 25
A23: 22 | B23: =B22-9 -> 345 | C23: =DATA!C345-DATA!E345 -> -256 | D23: =DATA!D345-DATA!F345 -> -45 | E23: =AVERAGE(C4:C23) -> -519.15 | F23: =AVERAGE(D4:D23) -> -1.4 | G23: =G22+C23 -> -12059 | H23: =H22+D23 -> -20
A24: 23 | B24: =B23-9 -> 336 | C24: =DATA!C336-DATA!E336 -> 583 | D24: =DATA!D336-DATA!F336 -> -5 | E24: =AVERAGE(C5:C24) -> -422.5 | F24: =AVERAGE(D5:D24) -> -2 | G24: =G23+C24 -> -11476 | H24: =H23+D24 -> -25
A25: 24 | B25: =B24-9 -> 327 | C25: =DATA!C327-DATA!E327 -> 73 | D25: =DATA!D327-DATA!F327 -> 5 | E25: =AVERAGE(C6:C25) -> -353.05 | F25: =AVERAGE(D6:D25) -> -1.65 | G25: =G24+C25 -> -11403 | H25: =H24+D25 -> -20
A26: 25 | B26: =B25-9 -> 318 | C26: =DATA!C318-DATA!E318 -> -51 | D26: =DATA!D318-DATA!F318 -> -2 | E26: =AVERAGE(C7:C26) -> -340.65 | F26: =AVERAGE(D7:D26) -> -1.8 | G26: =G25+C26 -> -11454 | H26: =H25+D26 -> -22
A27: 26 | B27: =B26-9 -> 309 | C27: =DATA!C309-DATA!E309 -> -240 | D27: =DATA!D309-DATA!F309 -> -4 | E27: =AVERAGE(C8:C27) -> -343.05 | F27: =AVERAGE(D8:D27) -> -2 | G27: =G26+C27 -> -11694 | H27: =H26+D27 -> -26
A28: 27 | B28: =B27-9 -> 300 | C28: =DATA!C300-DATA!E300 -> 146 | D28: =DATA!D300-DATA!F300 -> 1 | E28: =AVERAGE(C9:C28) -> -325.5 | F28: =AVERAGE(D9:D28) -> -1.9 | G28: =G27+C28 -> -11548 | H28: =H27+D28 -> -25
A29: 28 | B29: =B28-9 -> 291 | C29: =DATA!C291-DATA!E291 -> 401 | D29: =DATA!D291-DATA!F291 -> 11 | E29: =AVERAGE(C10:C29) -> -287.2 | F29: =AVERAGE(D10:D29) -> -1.3 | G29: =G28+C29 -> -11147 | H29: =H28+D29 -> -14
A30: 29 | B30: =B29-9 -> 282 | C30: =DATA!C282-DATA!E282 -> 603 | D30: =DATA!D282-DATA!F282 -> 3 | E30: =AVERAGE(C11:C30) -> -256.2 | F30: =AVERAGE(D11:D30) -> -0.95 | G30: =G29+C30 -> -10544 | H30: =H29+D30 -> -11
A31: 30 | B31: =B30-9 -> 273 | C31: =DATA!C273-DATA!E273 -> 69 | D31: =DATA!D273-DATA!F273 -> 4 | E31: =AVERAGE(C12:C31) -> -232.6 | F31: =AVERAGE(D12:D31) -> -1.15 | G31: =G30+C31 -> -10475 | H31: =H30+D31 -> -7
A32: 31 | B32: =B31-9 -> 264 | C32: =DATA!C264-DATA!E264 -> -41 | D32: =DATA!D264-DATA!F264 -> -1 | E32: =AVERAGE(C13:C32) -> -171 | F32: =AVERAGE(D13:D32) -> -1.15 | G32: =G31+C32 -> -10516 | H32: =H31+D32 -> -8
A33: 32 | B33: =B32-9 -> 255 | C33: =DATA!C255-DATA!E255 -> 525 | D33: =DATA!D255-DATA!F255 -> 8 | E33: =AVERAGE(C14:C33) -> -149.7 | F33: =AVERAGE(D14:D33) -> -0.85 | G33: =G32+C33 -> -9991 | H33: =H32+D33 -> 0
A34: 33 | B34: =B33-9 -> 246 | C34: =DATA!C246-DATA!E246 -> 162 | D34: =DATA!D246-DATA!F246 -> -1 | E34: =AVERAGE(C15:C34) -> -134.9 | F34: =AVERAGE(D15:D34) -> -1.05 | G34: =G33+C34 -> -9829 | H34: =H33+D34 -> -1
A35: 34 | B35: =B34-9 -> 237 | C35: =DATA!C237-DATA!E237 -> -193 | D35: =DATA!D237-DATA!F237 -> -2 | E35: =AVERAGE(C16:C35) -> -122.2 | F35: =AVERAGE(D16:D35) -> -1.5 | G35: =G34+C35 -> -10022 | H35: =H34+D35 -> -3
A36: 35 | B36: =B35-9 -> 228 | C36: =DATA!C228-DATA!E228 -> 177 | D36: =DATA!D228-DATA!F228 -> 4 | E36: =AVERAGE(C17:C36) -> -62.65 | F36: =AVERAGE(D17:D36) -> -1.55 | G36: =G35+C36 -> -9845 | H36: =H35+D36 -> 1
A37: 36 | B37: =B36-9 -> 219 | C37: =DATA!C219-DATA!E219 -> -768 | D37: =DATA!D219-DATA!F219 -> 0 | E37: =AVERAGE(C18:C37) -> -66.75 | F37: =AVERAGE(D18:D37) -> -1.6 | G37: =G36+C37 -> -10613 | H37: =H36+D37 -> 1
A38: 37 | B38: =B37-9 -> 210 | C38: =DATA!C210-DATA!E210 -> -361 | D38: =DATA!D210-DATA!F210 -> 2 | E38: =AVERAGE(C19:C38) -> 9.3 | F38: =AVERAGE(D19:D38) -> -1.5 | G38: =G37+C38 -> -10974 | H38: =H37+D38 -> 3
A39: 38 | B39: =B38-9 -> 201 | C39: =DATA!C201-DATA!E201 -> -208 | D39: =DATA!D201-DATA!F201 -> 2 | E39: =AVERAGE(C20:C39) -> 4.45 | F39: =AVERAGE(D20:D39) -> -1.35 | G39: =G38+C39 -> -11182 | H39: =H38+D39 -> 5
A40: 39 | B40: =B39-9 -> 192 | C40: =DATA!C192-DATA!E192 -> -932 | D40: =DATA!D192-DATA!F192 -> -4 | E40: =AVERAGE(C21:C40) -> -30.5 | F40: =AVERAGE(D21:D40) -> -1.5 | G40: =G39+C40 -> -12114 | H40: =H39+D40 -> 1
...

Sheet حجم هر نفر
B1: Cell Num. | C1: حقیقی هر نفر خرید | D1: حقیقی هر نفر فروش | E1: حقیقی هر نفر | F1: حقیقی هر نفر تجمعی | G1: حقوقی هر نفر خرید | H1: حقوقی هر نفر فروش | I1: حقوقی هر نفر | J1: حقوقی هر نفر تجمعی | K1: نسبت قدرت خریدار
A2: 1 | B2: =B3+9 -> 535 | C2: =IF(DATA!C534=0,0,(DATA!C535/DATA!C534)) -> 2482.1002 | D2: =IF(DATA!E534=0,0,(DATA!E535/DATA!E534)) -> 1620.8151 | E2: =C2-D2 -> 861.2851 | F2: =E2 -> 861.2851 | G2: =IF(DATA!D534=0,0,(DATA!D535/DATA!D534)) -> 228428.57 | H2: =IF(DATA!F534=0,0,(DATA!F535/DATA!F534)) -> 29499.778 | I2: =G2-H2 -> 198928.79 | J2: =I2 -> 198928.79 | K2: =(DATA!E534+DATA!F534)/(DATA!C534+DATA!D534) -> 2.1811709
A3: 2 | B3: =B4+9 -> 526 | C3: =IF(DATA!C525=0,0,(DATA!C526/DATA!C525)) -> 1659.7428 | D3: =IF(DATA!E525=0,0,(DATA!E526/DATA!E525)) -> 1792.4785 | E3: =C3-D3 -> -132.73565 | F3: =E3+F2 -> 728.54945 | G3: =IF(DATA!D525=0,0,(DATA!D526/DATA!D525)) -> 54595.059 | H3: =IF(DATA!F525=0,0,(DATA!F526/DATA!F525)) -> 46857.143 | I3: =G3-H3 -> 7737.916 | J3: =J2+I3 -> 206666.71 | K3: =(DATA!E525+DATA!F525)/(DATA!C525+DATA!D525) -> 1.0858264
A4: 3 | B4: =B5+9 -> 517 | C4: =IF(DATA!C516=0,0,(DATA!C517/DATA!C516)) -> 1606.7416 | D4: =IF(DATA!E516=0,0,(DATA!E517/DATA!E516)) -> 1586.2197 | E4: =C4-D4 -> 20.521834 | F4: =E4+F3 -> 749.07129 | G4: =IF(DATA!D516=0,0,(DATA!D517/DATA!D516)) -> 154357.14 | H4: =IF(DATA!F516=0,0,(DATA!F517/DATA!F516)) -> 6878.8571 | I4: =G4-H4 -> 147478.29 | J4: =J3+I4 -> 354145 | K4: =(DATA!E516+DATA!F516)/(DATA!C516+DATA!D516) -> 1.9955523
A5: 4 | B5: =B6+9 -> 508 | C5: =IF(DATA!C507=0,0,(DATA!C508/DATA!C507)) -> 2981.773 | D5: =IF(DATA!E507=0,0,(DATA!E508/DATA!E507)) -> 1736.4249 | E5: =C5-D5 -> 1245.3481 | F5: =E5+F4 -> 1994.4194 | G5: =IF(DATA!D507=0,0,(DATA!D508/DATA!D507)) -> 136333.33 | H5: =IF(DATA!F507=0,0,(DATA!F508/DATA!F507)) -> 40387.455 | I5: =G5-H5 -> 95945.879 | J5: =J4+I5 -> 450090.87 | K5: =(DATA!E507+DATA!F507)/(DATA!C507+DATA!D507) -> 2.0838816
A6: 5 | B6: =B7+9 -> 499 | C6: =IF(DATA!C498=0,0,(DATA!C499/DATA!C498)) -> 2265.2582 | D6: =IF(DATA!E498=0,0,(DATA!E499/DATA!E498)) -> 1560.3823 | E6: =C6-D6 -> 704.87594 | F6: =E6+F5 -> 2699.2953 | G6: =IF(DATA!D498=0,0,(DATA!D499/DATA!D498)) -> 94204 | H6: =IF(DATA!F498=0,0,(DATA!F499/DATA!F498)) -> 132269.5 | I6: =G6-H6 -> -38065.5 | J6: =J5+I6 -> 412025.37 | K6: =(DATA!E498+DATA!F498)/(DATA!C498+DATA!D498) -> 1.346915
A7: 6 | B7: =B8+9 -> 490 | C7: =IF(DATA!C489=0,0,(DATA!C490/DATA!C489)) -> 1466.5354 | D7: =IF(DATA!E489=0,0,(DATA!E490/DATA!E489)) -> 2013.986 | E7: =C7-D7 -> -547.45058 | F7: =E7+F6 -> 2151.8447 | G7: =IF(DATA!D489=0,0,(DATA!D490/DATA!D489)) -> 149583.33 | H7: =IF(DATA!F489=0,0,(DATA!F490/DATA!F489)) -> 47839.75 | I7: =G7-H7 -> 101743.58 | J7: =J6+I7 -> 513768.96 | K7: =(DATA!E489+DATA!F489)/(DATA!C489+DATA!D489) -> 1.125
A8: 7 | B8: =B9+9 -> 481 | C8: =IF(DATA!C480=0,0,(DATA!C481/DATA!C480)) -> 1787.9121 | D8: =IF(DATA!E480=0,0,(DATA!E481/DATA!E480)) -> 1597.3094 | E8: =C8-D8 -> 190.60267 | F8: =E8+F7 -> 2342.4474 | G8: =IF(DATA!D480=0,0,(DATA!D481/DATA!D480)) -> 111515.29 | H8: =IF(DATA!F480=0,0,(DATA!F481/DATA!F480)) -> 78263.25 | I8: =G8-H8 -> 33252.036 | J8: =J7+I8 -> 547020.99 | K8: =(DATA!E480+DATA!F480)/(DATA!C480+DATA!D480) -> 1.2246456
A9: 8 | B9: =B10+9 -> 472 | C9: =IF(DATA!C471=0,0,(DATA!C472/DATA!C471)) -> 1687.0504 | D9: =IF(DATA!E471=0,0,(DATA!E472/DATA!E471)) -> 1458.3615 | E9: =C9-D9 -> 228.68882 | F9: =E9+F8 -> 2571.1362 | G9: =IF(DATA!D471=0,0,(DATA!D472/DATA!D471)) -> 57137 | H9: =IF(DATA!F471=0,0,(DATA!F472/DATA!F471)) -> 9259.1429 | I9: =G9-H9 -> 47877.857 | J9: =J8+I9 -> 594898.85 | K9: =(DATA!E471+DATA!F471)/(DATA!C471+DATA!D471) -> 1.3273703
A10: 9 | B10: =B11+9 -> 463 | C10: =IF(DATA!C462=0,0,(DATA!C463/DATA!C462)) -> 1992.4171 | D10: =IF(DATA!E462=0,0,(DATA!E463/DATA!E462)) -> 1713.6194 | E10: =C10-D10 -> 278.79766 | F10: =E10+F9 -> 2849.9339 | G10: =IF(DATA!D462=0,0,(DATA!D463/DATA!D462)) -> 56765.5 | H10: =IF(DATA!F462=0,0,(DATA!F463/DATA!F462)) -> 61464.5 | I10: =G10-H10 -> -4699 | J10: =J9+I10 -> 590199.85 | K10: =(DATA!E462+DATA!F462)/(DATA!C462+DATA!D462) -> 1.01983
A11: 10 | B11: =B12+9 -> 454 | C11: =IF(DATA!C453=0,0,(DATA!C454/DATA!C453)) -> 2227.2727 | D11: =IF(DATA!E453=0,0,(DATA!E454/DATA!E453)) -> 2140.4456 | E11: =C11-D11 -> 86.827082 | F11: =E11+F10 -> 2936.761 | G11: =IF(DATA!D453=0,0,(DATA!D454/DATA!D453)) -> 74357.143 | H11: =IF(DATA!F453=0,0,(DATA!F454/DATA!F453)) -> 45304.667 | I11: =G11-H11 -> 29052.476 | J11: =J10+I11 -> 619252.33 | K11: =(DATA!E453+DATA!F453)/(DATA!C453+DATA!D453) -> 1.3617216
A12: 11 | B12: =B13+9 -> 445 | C12: =IF(DATA!C444=0,0,(DATA!C445/DATA!C444)) -> 2959.4595 | D12: =IF(DATA!E444=0,0,(DATA!E445/DATA!E444)) -> 1766.7746 | E12: =C12-D12 -> 1192.6848 | F12: =E12+F11 -> 4129.4458 | G12: =IF(DATA!D444=0,0,(DATA!D445/DATA!D444)) -> 351357.14 | H12: =IF(DATA!F444=0,0,(DATA!F445/DATA!F444)) -> 248600 | I12: =G12-H12 -> 102757.14 | J12: =J11+I12 -> 722009.47 | K12: =(DATA!E444+DATA!F444)/(DATA!C444+DATA!D444) -> 2.4124169
A13: 12 | B13: =B14+9 -> 436 | C13: =IF(DATA!C435=0,0,(DATA!C436/DATA!C435)) -> 1504.9885 | D13: =IF(DATA!E435=0,0,(DATA!E436/DATA!E435)) -> 2112.9568 | E13: =C13-D13 -> -607.96832 | F13: =E13+F12 -> 3521.4775 | G13: =IF(DATA!D435=0,0,(DATA!D436/DATA!D435)) -> 79481 | H13: =IF(DATA!F435=0,0,(DATA!F436/DATA!F435)) -> 26501.25 | I13: =G13-H13 -> 52979.75 | J13: =J12+I13 -> 774989.22 | K13: =(DATA!E435+DATA!F435)/(DATA!C435+DATA!D435) -> 0.92307692
A14: 13 | B14: =B15+9 -> 427 | C14: =IF(DATA!C426=0,0,(DATA!C427/DATA!C426)) -> 1568.1098 | D14: =IF(DATA!E426=0,0,(DATA!E427/DATA!E426)) -> 2235.8927 | E14: =C14-D14 -> -667.78287 | F14: =E14+F13 -> 2853.6946 | G14: =IF(DATA!D426=0,0,(DATA!D427/DATA!D426)) -> 131111.11 | H14: =IF(DATA!F426=0,0,(DATA!F427/DATA!F426)) -> 41405.667 | I14: =G14-H14 -> 89705.444 | J14: =J13+I14 -> 864694.66 | K14: =(DATA!E426+DATA!F426)/(DATA!C426+DATA!D426) -> 1.1370293
A15: 14 | B15: =B16+9 -> 418 | C15: =IF(DATA!C417=0,0,(DATA!C418/DATA!C417)) -> 1225.8953 | D15: =IF(DATA!E417=0,0,(DATA!E418/DATA!E417)) -> 6802.7344 | E15: =C15-D15 -> -5576.8391 | F15: =E15+F14 -> -2723.1445 | G15: =IF(DATA!D417=0,0,(DATA!D418/DATA!D417)) -> 1089833.3 | H15: =IF(DATA!F417=0,0,(DATA!F418/DATA!F417)) -> 792600 | I15: =G15-H15 -> 297233.33 | J15: =J14+I15 -> 1161928 | K15: =(DATA!E417+DATA!F417)/(DATA!C417+DATA!D417) -> 1.3996367
A16: 15 | B16: =B17+9 -> 409 | C16: =IF(DATA!C408=0,0,(DATA!C409/DATA!C408)) -> 2305.8712 | D16: =IF(DATA!E408=0,0,(DATA!E409/DATA!E408)) -> 4360.3865 | E16: =C16-D16 -> -2054.5153 | F16: =E16+F15 -> -4777.6597 | G16: =IF(DATA!D408=0,0,(DATA!D409/DATA!D408)) -> 534176.47 | H16: =IF(DATA!F408=0,0,(DATA!F409/DATA!F408)) -> 207500 | I16: =G16-H16 -> 326676.47 | J16: =J15+I16 -> 1488604.5 | K16: =(DATA!E408+DATA!F408)/(DATA!C408+DATA!D408) -> 1.9403541
A17: 16 | B17: =B18+9 -> 400 | C17: =IF(DATA!C399=0,0,(DATA!C400/DATA!C399)) -> 2022.0653 | D17: =IF(DATA!E399=0,0,(DATA!E400/DATA!E399)) -> 4043.4305 | E17: =C17-D17 -> -2021.3651 | F17: =E17+F16 -> -6799.0249 | G17: =IF(DATA!D399=0,0,(DATA!D400/DATA!D399)) -> 456307.69 | H17: =IF(DATA!F399=0,0,(DATA!F400/DATA!F399)) -> 72319.333 | I17: =G17-H17 -> 383988.36 | J17: =J16+I17 -> 1872592.8 | K17: =(DATA!E399+DATA!F399)/(DATA!C399+DATA!D399) -> 1.5977312
A18: 17 | B18: =B19+9 -> 391 | C18: =IF(DATA!C390=0,0,(DATA!C391/DATA!C390)) -> 8949.5268 | D18: =IF(DATA!E390=0,0,(DATA!E391/DATA!E390)) -> 3238.8712 | E18: =C18-D18 -> 5710.6556 | F18: =E18+F17 -> -1088.3693 | G18: =IF(DATA!D390=0,0,(DATA!D391/DATA!D390)) -> 530428.57 | H18: =IF(DATA!F390=0,0,(DATA!F391/DATA!F390)) -> 177000 | I18: =G18-H18 -> 353428.57 | J18: =J17+I18 -> 2226021.4 | K18: =(DATA!E390+DATA!F390)/(DATA!C390+DATA!D390) -> 3.9360374
