Workbook
Name A: DATA!$1:$1048576
Name DATA01: DATA!$AG$3:$AG$26
Name DATA02: DATA!$AH$3:$AH$26
Name DATA03: DATA!$AI$3:$AI$26
Name DATA04: DATA!$AJ$3:$AJ$26
Name INDEX: DATA!$AK$3:$AK$26

Sheet DATA
A1: 0.5 | B1: 0.05 | C1: 0.05 | D1: 0.05 | E1: 0.05 | F1: 0.05 | G1: 0.05 | H1: 0.05 | I1: 0.05 | J1: 0.05 | K1: 0.05 | L1: 0.05 | M1: 0.05 | N1: 0.05 | O1: 0.05 | P1: 0.05 | Q1: 0.05 | R1: 0.05 | S1: 0.05 | T1: 0.05 | U1: 0.05 | V1: 0.05 | W1: 0.05 | X1: 0.05 | Y1: 0.05
A2: DATA01 - PRICE | B2: DATA01 - SALE | C2: DATA01 - EPS | D2: DATA01 - B | E2: DATA01 - FCF | F2: DATA02 - PRICE | G2: DATA02 - SALE | H2: DATA02 - EPS | I2: DATA02 - B | J2: DATA02 - FCF | K2: DATA03 - PRICE | L2: DATA03 - SALE | M2: DATA03 - EPS | N2: DATA03 - B | O2: DATA03 - FCF | P2: DATA04 - PRICE | Q2: DATA04 - SALE | R2: DATA04 - EPS | S2: DATA04 - B | T2: DATA04 - FCF | U2: INDEX | V2: INDEX - SALE | W2: INDEX - EPS | X2: INDEX - B | Y2: INDEX - FCF | AG2: RETURN DATA 01 | AH2: RETURN DATA 02 | AI2: RETURN DATA 03 | AJ2: RETURN DATA 04 | AK2: RETURN DATA INDEX | AM2: PORTFOLIO | AO2: Downside DATA 01 | AP2: Downside DATA 02 | AQ2: Downside DATA 03 | AR2: Downside DATA 04 | AS2: Downside DATA INDEX
A3: =RANDBETWEEN(1500,3000) -> 2449 | B3: =RANDBETWEEN(1500,3000) -> 2136 | C3: =RANDBETWEEN(1500,3000) -> 2234 | D3: =RANDBETWEEN(1500,3000) -> 2911 | E3: =RANDBETWEEN(1500,3000) -> 1931 | F3: =RANDBETWEEN(850,1800) -> 1223 | G3: =RANDBETWEEN(850,1800) -> 963 | H3: =RANDBETWEEN(850,1800) -> 1193 | I3: =RANDBETWEEN(850,1800) -> 1045 | J3: =RANDBETWEEN(850,1800) -> 1151 | K3: =RANDBETWEEN(520,1250) -> 1182 | L3: =RANDBETWEEN(520,1250) -> 955 | M3: =RANDBETWEEN(520,1250) -> 986 | N3: =RANDBETWEEN(520,1250) -> 574 | O3: =RANDBETWEEN(520,1250) -> 633 | P3: =RANDBETWEEN(500,1000) -> 726 | Q3: =RANDBETWEEN(500,1000) -> 954 | R3: =RANDBETWEEN(500,1000) -> 784 | S3: =RANDBETWEEN(500,1000) -> 699 | T3: =RANDBETWEEN(500,1000) -> 804 | U3: =RANDBETWEEN(1000,2000) -> 1695 | V3: =RANDBETWEEN(1000,2000) -> 1914 | W3: =RANDBETWEEN(1000,2000) -> 1178 | X3: =RANDBETWEEN(1000,2000) -> 1488 | Y3: =RANDBETWEEN(1000,2000) -> 1214 | AA3: =A3*B3*C3*D3*E3 -> 6.5689761e+16 | AB3: =F3*G3*H3*I3*J3 -> 1.6899926e+15 | AC3: =K3*L3*M3*N3*O3 -> 404402065857720 | AD3: =P3*Q3*R3*S3*T3 -> 305164691225856 | AE3: =U3*V3*W3*X3*Y3 -> 6.9036465e+15 | AG3: =LN(AA4/AA3) -> -0.00032149876 | AH3: =LN(AB4/AB3) -> 0.0011049742 | AI3: =LN(AC4/AC3) -> -0.00035569638 | AJ3: =LN(AD4/AD3) -> 0.0014423634 | AK3: =LN(AE4/AE3) -> -5.5293164e-05 | AM3: =AG3+AH3+AI3+AJ3 -> 0.0018701426 | AO3: =MIN(AG3,0) -> -0.00032149876 | AP3: =MIN(AH3,0) -> 0 | AQ3: =MIN(AI3,0) -> -0.00035569638 | AR3: =MIN(AJ3,0) -> 0 | AS3: =MIN(AK3,0) -> -5.5293164e-05
A4: =A3+ $A$1 * RAND() * RANDBETWEEN(-1,1) -> 2449.0016 | B4: =B3+ $A$1 * RAND() * RANDBETWEEN(-1,1) -> 2135.5048 | C4: =C3+ $A$1 * RAND() * RANDBETWEEN(-1,1) -> 2234.0265 | D4: =D3+ $A$1 * RAND() * RANDBETWEEN(-1,1) -> 2911 | E4: =E3+ $A$1 * RAND() * RANDBETWEEN(-1,1) -> 1930.8028 | F4: =F3+ $A$1 * RAND() * RANDBETWEEN(-1,1) -> 1222.9863 | G4: =G3+ $A$1 * RAND() * RANDBETWEEN(-1,1) -> 963.49525 | H4: =H3+ $A$1 * RAND() * RANDBETWEEN(-1,1) -> 1193.3575 | ... Y4: =Y3+ $A$1 * RAND() * RANDBETWEEN(-1,1) -> 1214 | AA4: =A4*B4*C4*D4*E4 -> 6.5668645e+16 | AB4: =F4*G4*H4*I4*J4 -> 1.691861e+15 | AC4: =K4*L4*M4*N4*O4 -> 4.0425825e+14 | AD4: =P4*Q4*R4*S4*T4 -> 3.0560517e+14 | AE4: =U4*V4*W4*X4*Y4 -> 6.9032648e+15 | AG4: =LN(AA5/AA4) -> -0.00040704378 | AH4: =LN(AB5/AB4) -> 0.00038079916 | AI4: =LN(AC5/AC4) -> -0.00089773003 | AJ4: =LN(AD5/AD4) -> 0.00048216212 | AK4: =LN(AE5/AE4) -> -0.00013348752 | AM4: =AG4+AH4+AI4+AJ4 -> -0.00044181254 | AO4: =MIN(AG4,0) -> -0.00040704378 | AP4: =MIN(AH4,0) -> 0 | AQ4: =MIN(AI4,0) -> -0.00089773003 | AR4: =MIN(AJ4,0) -> 0 | AS4: =MIN(AK4,0) -> -0.00013348752
A5: =A4+ $A$1 * RAND() * RANDBETWEEN(-1,1) -> 2448.6642 | B5: =B4+ $A$1 * RAND() * RANDBETWEEN(-1,1) -> 2135.4183 | C5: =C4+ $A$1 * RAND() * RANDBETWEEN(-1,1) -> 2233.9927 | D5: =D4+ $A$1 * RAND() * RANDBETWEEN(-1,1) -> 2911.0163 | E5: =E4+ $A$1 * RAND() * RANDBETWEEN(-1,1) -> 1930.3795 | F5: =F4+ $A$1 * RAND() * RANDBETWEEN(-1,1) -> 1222.9072 | G5: =G4+ $A$1 * RAND() * RANDBETWEEN(-1,1) -> 963.60502 | H5: =H4+ $A$1 * RAND() * RANDBETWEEN(-1,1) -> 1193.3575 | ... Y5: =Y4+ $A$1 * RAND() * RANDBETWEEN(-1,1) -> 1214 | AA5: =A5*B5*C5*D5*E5 -> 6.5641921e+16 | AB5: =F5*G5*H5*I5*J5 -> 1.6925054e+15 | AC5: =K5*L5*M5*N5*O5 -> 4.038955e+14 | AD5: =P5*Q5*R5*S5*T5 -> 3.0575255e+14 | AE5: =U5*V5*W5*X5*Y5 -> 6.9023433e+15 | AG5: =LN(AA6/AA5) -> 0.00011195634 | AH5: =LN(AB6/AB5) -> 8.0367525e-05 | AI5: =LN(AC6/AC5) -> 0.00017225322 | AJ5: =LN(AD6/AD5) -> -0.00015844002 | AK5: =LN(AE6/AE5) -> -3.1538057e-06 | AM5: =AG5+AH5+AI5+AJ5 -> 0.00020613707 | AO5: =MIN(AG5,0) -> 0 | AP5: =MIN(AH5,0) -> 0 | AQ5: =MIN(AI5,0) -> 0 | AR5: =MIN(AJ5,0) -> -0.00015844002 | AS5: =MIN(AK5,0) -> -3.1538057e-06
A6: =A5+ $A$1 * RAND() * RANDBETWEEN(-1,1) -> 2449.0123 | B6: =B5+ $A$1 * RAND() * RANDBETWEEN(-1,1) -> 2135.6271 | C6: =C5+ $A$1 * RAND() * RANDBETWEEN(-1,1) -> 2233.5894 | D6: =D5+ $A$1 * RAND() * RANDBETWEEN(-1,1) -> 2911.0582 | E6: =E5+ $A$1 * RAND() * RANDBETWEEN(-1,1) -> 1930.4532 | F6: =F5+ $A$1 * RAND() * RANDBETWEEN(-1,1) -> 1222.9072 | G6: =G5+ $A$1 * RAND() * RANDBETWEEN(-1,1) -> 963.36692 | H6: =H5+ $A$1 * RAND() * RANDBETWEEN(-1,1) -> 1193.8257 | ... Y6: =Y5+ $A$1 * RAND() * RANDBETWEEN(-1,1) -> 1214 | AA6: =A6*B6*C6*D6*E6 -> 6.564927e+16 | AB6: =F6*G6*H6*I6*J6 -> 1.6926414e+15 | AC6: =K6*L6*M6*N6*O6 -> 403965073462351 | AD6: =P6*Q6*R6*S6*T6 -> 3.0570411e+14 | AE6: =U6*V6*W6*X6*Y6 -> 6.9023216e+15 | AG6: =LN(AA7/AA6) -> -0.00021120647 | AH6: =LN(AB7/AB6) -> -0.0005835855 | AI6: =LN(AC7/AC6) -> 0.00069581862 | AJ6: =LN(AD7/AD6) -> -2.9463708e-05 | AK6: =LN(AE7/AE6) -> -0.00012791877 | AM6: =AG6+AH6+AI6+AJ6 -> -0.00012843705 | AO6: =MIN(AG6,0) -> -0.00021120647 | AP6: =MIN(AH6,0) -> -0.0005835855 | AQ6: =MIN(AI6,0) -> 0 | AR6: =MIN(AJ6,0) -> -2.9463708e-05 | AS6: =MIN(AK6,0) -> -0.00012791877
A7: =A6+ $A$1 * RAND() * RANDBETWEEN(-1,1) -> 2449.0123 | B7: =B6+ $A$1 * RAND() * RANDBETWEEN(-1,1) -> 2135.7267 | C7: =C6+ $A$1 * RAND() * RANDBETWEEN(-1,1) -> 2233.4504 | D7: =D6+ $A$1 * RAND() * RANDBETWEEN(-1,1) -> 2911.0582 | E7: =E6+ $A$1 * RAND() * RANDBETWEEN(-1,1) -> 1930.0756 | F7: =F6+ $A$1 * RAND() * RANDBETWEEN(-1,1) -> 1222.9072 | G7: =G6+ $A$1 * RAND() * RANDBETWEEN(-1,1) -> 963.03084 | H7: =H6+ $A$1 * RAND() * RANDBETWEEN(-1,1) -> 1193.5455 | ... Y7: =Y6+ $A$1 * RAND() * RANDBETWEEN(-1,1) -> 1214 | AA7: =A7*B7*C7*D7*E7 -> 6.5635406e+16 | AB7: =F7*G7*H7*I7*J7 -> 1.6916539e+15 | AC7: =K7*L7*M7*N7*O7 -> 4.0424626e+14 | AD7: =P7*Q7*R7*S7*T7 -> 3.0569511e+14 | AE7: =U7*V7*W7*X7*Y7 -> 6.9014387e+15 | AG7: =LN(AA8/AA7) -> -0.00013271543 | AH7: =LN(AB8/AB7) -> -0.00011670901 | AI7: =LN(AC8/AC7) -> -0.00082168571 | AJ7: =LN(AD8/AD7) -> 5.7190058e-05 | AK7: =LN(AE8/AE7) -> -0.00061724331 | AM7: =AG7+AH7+AI7+AJ7 -> -0.0010139201 | AO7: =MIN(AG7,0) -> -0.00013271543 | AP7: =MIN(AH7,0) -> -0.00011670901 | AQ7: =MIN(AI7,0) -> -0.00082168571 | AR7: =MIN(AJ7,0) -> 0 | AS7: =MIN(AK7,0) -> -0.00061724331
A8: =A7+ $A$1 * RAND() * RANDBETWEEN(-1,1) -> 2449.045 | B8: =B7+ $A$1 * RAND() * RANDBETWEEN(-1,1) -> 2135.4081 | C8: =C7+ $A$1 * RAND() * RANDBETWEEN(-1,1) -> 2233.4633 | D8: =D7+ $A$1 * RAND() * RANDBETWEEN(-1,1) -> 2911.0582 | E8: =E7+ $A$1 * RAND() * RANDBETWEEN(-1,1) -> 1930.0706 | F8: =F7+ $A$1 * RAND() * RANDBETWEEN(-1,1) -> 1222.9072 | G8: =G7+ $A$1 * RAND() * RANDBETWEEN(-1,1) -> 963.23211 | H8: =H7+ $A$1 * RAND() * RANDBETWEEN(-1,1) -> 1193.5455 | ... Y8: =Y7+ $A$1 * RAND() * RANDBETWEEN(-1,1) -> 1213.5215 | AA8: =A8*B8*C8*D8*E8 -> 6.5626696e+16 | AB8: =F8*G8*H8*I8*J8 -> 1.6914565e+15 | AC8: =K8*L8*M8*N8*O8 -> 4.0391423e+14 | AD8: =P8*Q8*R8*S8*T8 -> 3.0571259e+14 | AE8: =U8*V8*W8*X8*Y8 -> 6.8971801e+15 | AG8: =LN(AA9/AA8) -> 0.00024485976 | AH8: =LN(AB9/AB8) -> -0.00022753316 | AI8: =LN(AC9/AC8) -> 0.00080799388 | AJ8: =LN(AD9/AD8) -> -0.00090630525 | AK8: =LN(AE9/AE8) -> 0.00075469442 | AM8: =AG8+AH8+AI8+AJ8 -> -8.0984761e-05 | AO8: =MIN(AG8,0) -> 0 | AP8: =MIN(AH8,0) -> -0.00022753316 | AQ8: =MIN(AI8,0) -> 0 | AR8: =MIN(AJ8,0) -> -0.00090630525 | AS8: =MIN(AK8,0) -> 0
A9: =A8+ $A$1 * RAND() * RANDBETWEEN(-1,1) -> 2449.0499 | B9: =B8+ $A$1 * RAND() * RANDBETWEEN(-1,1) -> 2135.4081 | C9: =C8+ $A$1 * RAND() * RANDBETWEEN(-1,1) -> 2233.9326 | D9: =D8+ $A$1 * RAND() * RANDBETWEEN(-1,1) -> 2911.45 | E9: =E8+ $A$1 * RAND() * RANDBETWEEN(-1,1) -> 1929.874 | F9: =F8+ $A$1 * RAND() * RANDBETWEEN(-1,1) -> 1222.9072 | G9: =G8+ $A$1 * RAND() * RANDBETWEEN(-1,1) -> 963.47593 | H9: =H8+ $A$1 * RAND() * RANDBETWEEN(-1,1) -> 1193.5455 | ... Y9: =Y8+ $A$1 * RAND() * RANDBETWEEN(-1,1) -> 1213.7084 | AA9: =A9*B9*C9*D9*E9 -> 6.5642767e+16 | AB9: =F9*G9*H9*I9*J9 -> 1.6910717e+15 | AC9: =K9*L9*M9*N9*O9 -> 4.0424072e+14 | AD9: =P9*Q9*R9*S9*T9 -> 3.0543565e+14 | AE9: =U9*V9*W9*X9*Y9 -> 6.9023874e+15 | AG9: =LN(AA10/AA9) -> -0.00033940246 | AH9: =LN(AB10/AB9) -> -0.00017957485 | AI9: =LN(AC10/AC9) -> 8.6878026e-05 | AJ9: =LN(AD10/AD9) -> -0.00038002652 | AK9: =LN(AE10/AE9) -> 0.00038798487 | AM9: =AG9+AH9+AI9+AJ9 -> -0.0008121258 | AO9: =MIN(AG9,0) -> -0.00033940246 | AP9: =MIN(AH9,0) -> -0.00017957485 | AQ9: =MIN(AI9,0) -> 0 | AR9: =MIN(AJ9,0) -> -0.00038002652 | AS9: =MIN(AK9,0) -> 0
A10: =A9+ $A$1 * RAND() * RANDBETWEEN(-1,1) -> 2449.0499 | B10: =B9+ $A$1 * RAND() * RANDBETWEEN(-1,1) -> 2135.4081 | C10: =C9+ $A$1 * RAND() * RANDBETWEEN(-1,1) -> 2233.8232 | D10: =D9+ $A$1 * RAND() * RANDBETWEEN(-1,1) -> 2911.1763 | E10: =E9+ $A$1 * RAND() * RANDBETWEEN(-1,1) -> 1929.495 | F10: =F9+ $A$1 * RAND() * RANDBETWEEN(-1,1) -> 1222.9072 | G10: =G9+ $A$1 * RAND() * RANDBETWEEN(-1,1) -> 963.88699 | H10: =H9+ $A$1 * RAND() * RANDBETWEEN(-1,1) -> 1193.1882 | ... Y10: =Y9+ $A$1 * RAND() * RANDBETWEEN(-1,1) -> 1213.7084 | AA10: =A10*B10*C10*D10*E10 -> 6.5620491e+16 | AB10: =F10*G10*H10*I10*J10 -> 1.690768e+15 | AC10: =K10*L10*M10*N10*O10 -> 4.0427584e+14 | AD10: =P10*Q10*R10*S10*T10 -> 305319595544385 | AE10: =U10*V10*W10*X10*Y10 -> 6.9050659e+15 | AG10: =LN(AA11/AA10) -> 5.0861704e-05 | AH10: =LN(AB11/AB10) -> -0.00035303616 | AI10: =LN(AC11/AC10) -> -0.0011051007 | AJ10: =LN(AD11/AD10) -> -0.00019717297 | AK10: =LN(AE11/AE10) -> 0.00023077084 | AM10: =AG10+AH10+AI10+AJ10 -> -0.0016044481 | AO10: =MIN(AG10,0) -> 0 | AP10: =MIN(AH10,0) -> -0.00035303616 | AQ10: =MIN(AI10,0) -> -0.0011051007 | AR10: =MIN(AJ10,0) -> -0.00019717297 | AS10: =MIN(AK10,0) -> 0
A11: =A10+ $A$1 * RAND() * RANDBETWEEN(-1,1) -> 2448.975 | B11: =B10+ $A$1 * RAND() * RANDBETWEEN(-1,1) -> 2135.4081 | C11: =C10+ $A$1 * RAND() * RANDBETWEEN(-1,1) -> 2234.0051 | D11: =D10+ $A$1 * RAND() * RANDBETWEEN(-1,1) -> 2911.1763 | E11: =E10+ $A$1 * RAND() * RANDBETWEEN(-1,1) -> 1929.495 | F11: =F10+ $A$1 * RAND() * RANDBETWEEN(-1,1) -> 1222.9072 | G11: =G10+ $A$1 * RAND() * RANDBETWEEN(-1,1) -> 963.6152 | H11: =H10+ $A$1 * RAND() * RANDBETWEEN(-1,1) -> 1193.1643 | ... Y11: =Y10+ $A$1 * RAND() * RANDBETWEEN(-1,1) -> 1213.2255 | AA11: =A11*B11*C11*D11*E11 -> 6.5623829e+16 | AB11: =F11*G11*H11*I11*J11 -> 1.6901712e+15 | AC11: =K11*L11*M11*N11*O11 -> 4.0382933e+14 | AD11: =P11*Q11*R11*S11*T11 -> 3.052594e+14 | AE11: =U11*V11*W11*X11*Y11 -> 6.9066596e+15 | AG11: =LN(AA12/AA11) -> 9.4501139e-05 | AH11: =LN(AB12/AB11) -> -0.0001611734 | AI11: =LN(AC12/AC11) -> -0.001087728 | AJ11: =LN(AD12/AD11) -> 0.00040723739 | AK11: =LN(AE12/AE11) -> 0.00036803124 | AM11: =AG11+AH11+AI11+AJ11 -> -0.00074716283 | AO11: =MIN(AG11,0) -> 0 | AP11: =MIN(AH11,0) -> -0.0001611734 | AQ11: =MIN(AI11,0) -> -0.001087728 | AR11: =MIN(AJ11,0) -> 0 | AS11: =MIN(AK11,0) -> 0
A12: =A11+ $A$1 * RAND() * RANDBETWEEN(-1,1) -> 2448.7026 | B12: =B11+ $A$1 * RAND() * RANDBETWEEN(-1,1) -> 2135.4081 | C12: =C11+ $A$1 * RAND() * RANDBETWEEN(-1,1) -> 2234.0051 | D12: =D11+ $A$1 * RAND() * RANDBETWEEN(-1,1) -> 2911.1763 | E12: =E11+ $A$1 * RAND() * RANDBETWEEN(-1,1) -> 1929.892 | F12: =F11+ $A$1 * RAND() * RANDBETWEEN(-1,1) -> 1222.8754 | G12: =G11+ $A$1 * RAND() * RANDBETWEEN(-1,1) -> 963.6152 | H12: =H11+ $A$1 * RAND() * RANDBETWEEN(-1,1) -> 1192.8823 | ... Y12: =Y11+ $A$1 * RAND() * RANDBETWEEN(-1,1) -> 1213.2255 | AA12: =A12*B12*C12*D12*E12 -> 6.5630031e+16 | AB12: =F12*G12*H12*I12*J12 -> 1.6898989e+15 | AC12: =K12*L12*M12*N12*O12 -> 4.0339031e+14 | AD12: =P12*Q12*R12*S12*T12 -> 3.0538374e+14 | AE12: =U12*V12*W12*X12*Y12 -> 6.9092019e+15 | AG12: =LN(AA13/AA12) -> 0.00023311567 | AH12: =LN(AB13/AB12) -> 0.00055447711 | AI12: =LN(AC13/AC12) -> 0.00059547956 | AJ12: =LN(AD13/AD12) -> -0.0013860033 | AK12: =LN(AE13/AE12) -> 0.00015279728 | AM12: =AG12+AH12+AI12+AJ12 -> -2.9309682e-06 | AO12: =MIN(AG12,0) -> 0 | AP12: =MIN(AH12,0) -> 0 | AQ12: =MIN(AI12,0) -> 0 | AR12: =MIN(AJ12,0) -> -0.0013860033 | AS12: =MIN(AK12,0) -> 0
A13: =A12+ $A$1 * RAND() * RANDBETWEEN(-1,1) -> 2448.7772 | B13: =B12+ $A$1 * RAND() * RANDBETWEEN(-1,1) -> 2135.5263 | C13: =C12+ $A$1 * RAND() * RANDBETWEEN(-1,1) -> 2234.0051 | D13: =D12+ $A$1 * RAND() * RANDBETWEEN(-1,1) -> 2910.9206 | E13: =E12+ $A$1 * RAND() * RANDBETWEEN(-1,1) -> 1930.3458 | F13: =F12+ $A$1 * RAND() * RANDBETWEEN(-1,1) -> 1223.2554 | G13: =G12+ $A$1 * RAND() * RANDBETWEEN(-1,1) -> 963.85007 | H13: =H12+ $A$1 * RAND() * RANDBETWEEN(-1,1) -> 1192.8823 | ... Y13: =Y12+ $A$1 * RAND() * RANDBETWEEN(-1,1) -> 1213.1082 | AA13: =A13*B13*C13*D13*E13 -> 6.5645332e+16 | AB13: =F13*G13*H13*I13*J13 -> 1.6908361e+15 | AC13: =K13*L13*M13*N13*O13 -> 4.0363059e+14 | AD13: =P13*Q13*R13*S13*T13 -> 3.0496077e+14 | AE13: =U13*V13*W13*X13*Y13 -> 6.9102577e+15 | AG13: =LN(AA14/AA13) -> -0.00010391824 | AH13: =LN(AB14/AB13) -> 0.0005640269 | AI13: =LN(AC14/AC13) -> -0.0005636123 | AJ13: =LN(AD14/AD13) -> -0.0001681582 | AK13: =LN(AE14/AE13) -> 0.00024978378 | AM13: =AG13+AH13+AI13+AJ13 -> -0.00027166183 | AO13: =MIN(AG13,0) -> -0.00010391824 | AP13: =MIN(AH13,0) -> 0 | AQ13: =MIN(AI13,0) -> -0.0005636123 | AR13: =MIN(AJ13,0) -> -0.0001681582 | AS13: =MIN(AK13,0) -> 0
A14: =A13+ $A$1 * RAND() * RANDBETWEEN(-1,1) -> 2449.1416 | B14: =B13+ $A$1 * RAND() * RANDBETWEEN(-1,1) -> 2135.0618 | C14: =C13+ $A$1 * RAND() * RANDBETWEEN(-1,1) -> 2234.0051 | D14: =D13+ $A$1 * RAND() * RANDBETWEEN(-1,1) -> 2910.8182 | E14: =E13+ $A$1 * RAND() * RANDBETWEEN(-1,1) -> 1930.3458 | F14: =F13+ $A$1 * RAND() * RANDBETWEEN(-1,1) -> 1223.2554 | G14: =G13+ $A$1 * RAND() * RANDBETWEEN(-1,1) -> 963.85007 | H14: =H13+ $A$1 * RAND() * RANDBETWEEN(-1,1) -> 1192.8938 | ... Y14: =Y13+ $A$1 * RAND() * RANDBETWEEN(-1,1) -> 1213.1788 | AA14: =A14*B14*C14*D14*E14 -> 6.5638511e+16 | AB14: =F14*G14*H14*I14*J14 -> 1.6917901e+15 | AC14: =K14*L14*M14*N14*O14 -> 4.0340316e+14 | AD14: =P14*Q14*R14*S14*T14 -> 3.0490949e+14 | AE14: =U14*V14*W14*X14*Y14 -> 6.911984e+15 | AG14: =LN(AA15/AA14) -> 0.00021542958 | AH14: =LN(AB15/AB14) -> 3.5108459e-05 | AI14: =LN(AC15/AC14) -> -0.00023259234 | AJ14: =LN(AD15/AD14) -> -0.00030796694 | AK14: =LN(AE15/AE14) -> 0.00015856074 | AM14: =AG14+AH14+AI14+AJ14 -> -0.00029002123 | AO14: =MIN(AG14,0) -> 0 | AP14: =MIN(AH14,0) -> 0 | AQ14: =MIN(AI14,0) -> -0.00023259234 | AR14: =MIN(AJ14,0) -> -0.00030796694 | AS14: =MIN(AK14,0) -> 0
A15: =A14+ $A$1 * RAND() * RANDBETWEEN(-1,1) -> 2449.2397 | B15: =B14+ $A$1 * RAND() * RANDBETWEEN(-1,1) -> 2135.0618 | C15: =C14+ $A$1 * RAND() * RANDBETWEEN(-1,1) -> 2234.4017 | D15: =D14+ $A$1 * RAND() * RANDBETWEEN(-1,1) -> 2910.5082 | E15: =E14+ $A$1 * RAND() * RANDBETWEEN(-1,1) -> 1930.5474 | F15: =F14+ $A$1 * RAND() * RANDBETWEEN(-1,1) -> 1223.4672 | G15: =G14+ $A$1 * RAND() * RANDBETWEEN(-1,1) -> 964.17571 | H15: =H14+ $A$1 * RAND() * RANDBETWEEN(-1,1) -> 1192.8938 | ... Y15: =Y14+ $A$1 * RAND() * RANDBETWEEN(-1,1) -> 1212.8772 | AA15: =A15*B15*C15*D15*E15 -> 6.5652653e+16 | AB15: =F15*G15*H15*I15*J15 -> 1.6918495e+15 | AC15: =K15*L15*M15*N15*O15 -> 4.0330935e+14 | AD15: =P15*Q15*R15*S15*T15 -> 3.048156e+14 | AE15: =U15*V15*W15*X15*Y15 -> 6.91308e+15 | AG15: =LN(AA16/AA15) -> -0.00022202052 | AH15: =LN(AB16/AB15) -> 0.00019706636 | AI15: =LN(AC16/AC15) -> -0.00045452992 | AJ15: =LN(AD16/AD15) -> -7.7043074e-05 | AK15: =LN(AE16/AE15) -> 2.4755053e-05 | AM15: =AG15+AH15+AI15+AJ15 -> -0.00055652715 | AO15: =MIN(AG15,0) -> -0.00022202052 | AP15: =MIN(AH15,0) -> 0 | AQ15: =MIN(AI15,0) -> -0.00045452992 | AR15: =MIN(AJ15,0) -> -7.7043074e-05 | AS15: =MIN(AK15,0) -> 0
... A1000: =A999+ $A$1 * RAND() * RANDBETWEEN(-1,1) -> 2448.397 | B1000: =B999+ $A$1 * RAND() * RANDBETWEEN(-1,1) -> 2137.5237 | C1000: =C999+ $A$1 * RAND() * RANDBETWEEN(-1,1) -> 2235.185 | D1000: =D999+ $A$1 * RAND() * RANDBETWEEN(-1,1) -> 2906.331 | E1000: =E999+ $A$1 * RAND() * RANDBETWEEN(-1,1) -> 1929.0285 | F1000: =F999+ $A$1 * RAND() * RANDBETWEEN(-1,1) -> 1217.5941 | G1000: =G999+ $A$1 * RAND() * RANDBETWEEN(-1,1) -> 971.32564 | H1000: =H999+ $A$1 * RAND() * RANDBETWEEN(-1,1) -> 1191.4086 | ... Y1000: =Y999+ $A$1 * RAND() * RANDBETWEEN(-1,1) -> 1202.4764 | AA1000: =A1000*B1000*C1000*D1000*E1000 -> 6.5582803e+16 | AB1000: =F1000*G1000*H1000*I1000*J1000 -> 1.6953972e+15 | AC1000: =K1000*L1000*M1000*N1000*O1000 -> 4.0566549e+14 | AD1000: =P1000*Q1000*R1000*S1000*T1000 -> 3.0238087e+14 | AE1000: =U1000*V1000*W1000*X1000*Y1000 -> 6.941345e+15 | AG1000: =LN(AA1001/AA1000) -> -0.00013444585 | AH1000: =LN(AB1001/AB1000) -> 9.8347884e-05 | AI1000: =LN(AC1001/AC1000) -> -0.00014453623 | AJ1000: =LN(AD1001/AD1000) -> -0.00053706501 | AK1000: =LN(AE1001/AE1000) -> 0.00018915458 | AM1000: =AG1000+AH1000+AI1000+AJ1000 -> -0.0007176992 | AO1000: =MIN(AG1000,0) -> -0.00013444585 | AP1000: =MIN(AH1000,0) -> 0 | AQ1000: =MIN(AI1000,0) -> -0.00014453623 | AR1000: =MIN(AJ1000,0) -> -0.00053706501 | AS1000: =MIN(AK1000,0) -> 0
A1001: =A1000+ $A$1 * RAND() * RANDBETWEEN(-1,1) -> 2448.3942 | B1001: =B1000+ $A$1 * RAND() * RANDBETWEEN(-1,1) -> 2137.5237 | C1001: =C1000+ $A$1 * RAND() * RANDBETWEEN(-1,1) -> 2235.185 | D1001: =D1000+ $A$1 * RAND() * RANDBETWEEN(-1,1) -> 2905.9436 | E1001: =E1000+ $A$1 * RAND() * RANDBETWEEN(-1,1) -> 1929.0285 | F1001: =F1000+ $A$1 * RAND() * RANDBETWEEN(-1,1) -> 1217.2951 | G1001: =G1000+ $A$1 * RAND() * RANDBETWEEN(-1,1) -> 970.90656 | H1001: =H1000+ $A$1 * RAND() * RANDBETWEEN(-1,1) -> 1191.8221 | ... Y1001: =Y1000+ $A$1 * RAND() * RANDBETWEEN(-1,1) -> 1202.9509 | AA1001: =A1001*B1001*C1001*D1001*E1001 -> 6.5573986e+16 | AB1001: =F1001*G1001*H1001*I1001*J1001 -> 1.6955639e+15 | AC1001: =K1001*L1001*M1001*N1001*O1001 -> 4.0560686e+14 | AD1001: =P1001*Q1001*R1001*S1001*T1001 -> 3.0221852e+14 | AE1001: =U1001*V1001*W1001*X1001*Y1001 -> 6.9426581e+15
A1002: =A1001+ $A$1 * RAND() * RANDBETWEEN(-1,1) -> 2448.3942 | B1002: =B1001+ $A$1 * RAND() * RANDBETWEEN(-1,1) -> 2137.2926 | C1002: =C1001+ $A$1 * RAND() * RANDBETWEEN(-1,1) -> 2235.185 | D1002: =D1001+ $A$1 * RAND() * RANDBETWEEN(-1,1) -> 2906.4046 | E1002: =E1001+ $A$1 * RAND() * RANDBETWEEN(-1,1) -> 1929.1818 | F1002: =F1001+ $A$1 * RAND() * RANDBETWEEN(-1,1) -> 1216.9597 | G1002: =G1001+ $A$1 * RAND() * RANDBETWEEN(-1,1) -> 970.86904 | H1002: =H1001+ $A$1 * RAND() * RANDBETWEEN(-1,1) -> 1191.3288 | ... Y1002: =Y1001+ $A$1 * RAND() * RANDBETWEEN(-1,1) -> 1202.4614

Sheet ANALYSIS
A1: Optimal Weights:
A2: DATA01 Weight | B2: 0.2226259 | T2: =DATA!AM3*$B$7 -> 374028.51
A3: DATA02 Weight | B3: 0.20381638 | N3: Risk-Free rate | O3: DATA01 Weight | P3: DATA02 Weight | Q3: DATA03 Weight | R3: DATA04 Weight | T3: =DATA!AM4*$B$7 -> -88362.507
A4: DATA03 Weight | B4: 0.30227005 | N4: 0.01 | O4: 0.2878 | P4: 0.2359 | Q4: 0.2394 | R4: 0.2369 | T4: =DATA!AM5*$B$7 -> 41227.413
A5: DATA04 Weight | B5: 0.27128771 | N5: 0.05 | O5: 0.2862 | P5: 0.225 | Q5: 0.2508 | R5: 0.238 | T5: =DATA!AM6*$B$7 -> -25687.41
A6: Assumation | N6: 0.1 | O6: 0.2381 | P6: 0.2513 | Q6: 0.2562 | R6: 0.2544 | T6: =DATA!AM7*$B$7 -> -202784.02
A7: Portfolio Value (Price): | B7: 200000000 | N7: 0.15 | O7: 0.2408 | P7: 0.2556 | Q7: 0.2512 | R7: 0.2524 | T7: =DATA!AM8*$B$7 -> -16196.952
A8: Annualised Risk-Free Rate: | B8: 0.25 | N8: 0.2 | O8: 0.2301 | P8: 0.2599 | Q8: 0.2542 | R8: 0.2558 | T8: =DATA!AM9*$B$7 -> -162425.16
A9: Confidence Interval: | B9: 0.95 | T9: =DATA!AM10*$B$7 -> -320889.62
A10: Annual Investing Days: | B10: 220
A11: Expected Returns: | B11: Annualised Return | C11: Variance | D11: Annualised Risk | E11: Semi Deviation | F11: Covariance | G11: Beta | H11: Correlation | I11: Expected Returns (CAPM) | J11: Sharp Ratio | K11: Treynor Ratio | L11: Sortino Ratio | T11: =DATA!AM11*$B$7 -> -149432.57
A12: DATA01 | B12: {=PRODUCT(1+_xlfn.SINGLE(DATA!AG3:AG1000))^(1/$B$10)-1} -> 1.0594938e-06 | C12: =_xlfn.VAR.S(DATA!AG3:AG1000) -> 5.3558444e-08 | D12: =_xlfn.STDEV.S(DATA!AG3:AG1000)*SQRT($B$10) -> 0.0034326167 | E12: =SQRT(SUMSQ(DATA!AO3:AO1000)/COUNT(DATA!AO3:AO1000))*SQRT(ANALYSIS!B10) -> 0.0024240094 | F12: =_xlfn.COVARIANCE.S(DATA!AK3:AK1000,DATA!AG3:AG1000) -> 5.4162774e-09 | G12: =F12/C12 -> 0.10112836 | H12: =CORREL(DATA!AG3:AG1000,DATA!AK3:AK1000) -> 0.064760654 | I12: =$B$8+G12*(B12-$B$8) -> 0.22471802 | J12: =(B12-$B$8)/D12 -> -72.830426 | K12: =(B12-$B$8)/G12 -> -2.4720954 | L12: =(B12-$B$8)/E12 -> -103.13448 | T12: =DATA!AM12*$B$7 -> -586.19363
A13: DATA02 | B13: =PRODUCT(1+DATA!AH3:AH1000)^(1/$B$10)-1 -> 2.5630392e-06 | C13: =_xlfn.VAR.S(DATA!AH3:AH1000) -> 2.5098778e-07 | D13: =_xlfn.STDEV.S(DATA!AH3:AH1000)*SQRT($B$10) -> 0.0074308352 | E13: =SQRT(SUMSQ(DATA!AP3:AP1000)/COUNT(DATA!AP3:AP1000))*SQRT(ANALYSIS!B10) -> 0.0051932809 | F13: =_xlfn.COVARIANCE.S(DATA!AK3:AK1000,DATA!AH3:AH1000) -> -1.7701937e-09 | G13: =F13/C13 -> -0.0070529077 | H13: =CORREL(DATA!AH3:AH1000,DATA!AK3:AK1000) -> -0.0097772967 | I13: =$B$8+G13*(B13-$B$8) -> 0.25176321 | J13: =(B13-$B$8)/D13 -> -33.643249 | K13: =(B13-$B$8)/G13 -> 35.44601 | L13: =(B13-$B$8)/E13 -> -48.138632 | T13: =DATA!AM13*$B$7 -> -54332.365
A14: DATA03 | B14: =PRODUCT(1+DATA!AI3:AI1000)^(1/$B$10)-1 -> -1.0573603e-06 | C14: =_xlfn.VAR.S(DATA!AI3:AI1000) -> 4.5558758e-07 | D14: =_xlfn.STDEV.S(DATA!AI3:AI1000)*SQRT($B$10) -> 0.010011457 | E14: =SQRT(SUMSQ(DATA!AQ3:AQ1000)/COUNT(DATA!AQ3:AQ1000))*SQRT(ANALYSIS!B10) -> 0.0069278136 | F14: =_xlfn.COVARIANCE.S(DATA!AK3:AK1000,DATA!AI3:AI1000) -> -1.0340402e-08 | G14: =F14/C14 -> -0.022696848 | H14: =CORREL(DATA!AI3:AI1000,DATA!AK3:AK1000) -> -0.042391209 | I14: =$B$8+G14*(B14-$B$8) -> 0.25567424 | J14: =(B14-$B$8)/D14 -> -24.971496 | K14: =(B14-$B$8)/G14 -> 11.014792 | L14: =(B14-$B$8)/E14 -> -36.086574 | T14: =DATA!AM14*$B$7 -> -58004.247
A15: DATA04 | B15: =PRODUCT(1+DATA!AJ3:AJ1000)^(1/$B$10)-1 -> -3.5020922e-07 | C15: =_xlfn.VAR.S(DATA!AJ3:AJ1000) -> 4.6185621e-07 | D15: =_xlfn.STDEV.S(DATA!AJ3:AJ1000)*SQRT($B$10) -> 0.010080098 | E15: =SQRT(SUMSQ(DATA!AR3:AR1000)/COUNT(DATA!AR3:AR1000))*SQRT(ANALYSIS!B10) -> 0.0072581479 | F15: =_xlfn.COVARIANCE.S(DATA!AK3:AK1000,DATA!AJ3:AJ1000) -> -1.3502659e-08 | G15: =F15/C15 -> -0.029235634 | H15: =SLOPE(DATA!AJ3:AJ1000,DATA!AG3:AG1000) -> -0.13490595 | I15: =$B$8+G15*(B15-$B$8) -> 0.25730892 | J15: =(B15-$B$8)/D15 -> -24.801382 | K15: =(B15-$B$8)/G15 -> 8.5512203 | L15: =(B15-$B$8)/E15 -> -34.444097 | T15: =DATA!AM15*$B$7 -> -111305.43
A16: Correlation Matrix: | B16: 1 | C16: 2 | D16: 3 | E16: 4 | F16: 5 | T16: =DATA!AM16*$B$7 -> 34763.885
A17: 1 | B17: =CORREL(INDEX(DATA!$AG$3:$AK$3,$A$17):INDEX(DATA!$AG$1000:$AK$1000,$A$17),INDEX(DATA!$AG$3:$AK$3,B16):INDEX(DATA!$AG$1000:$AK$1000,B16)) -> 1 | C17: =CORREL(INDEX(DATA!$AG$3:$AK$3,$A$17):INDEX(DATA!$AG$1000:$AK$1000,$A$17),INDEX(DATA!$AG$3:$AK$3,C16):INDEX(DATA!$AG$1000:$AK$1000,C16)) -> -0.037573046 | D17: =CORREL(INDEX(DATA!$AG$3:$AK$3,$A$17):INDEX(DATA!$AG$1000:$AK$1000,$A$17),INDEX(DATA!$AG$3:$AK$3,D16):INDEX(DATA!$AG$1000:$AK$1000,D16)) -> -0.021560812 | E17: =CORREL(INDEX(DATA!$AG$3:$AK$3,$A$17):INDEX(DATA!$AG$1000:$AK$1000,$A$17),INDEX(DATA!$AG$3:$AK$3,E16):INDEX(DATA!$AG$1000:$AK$1000,E16)) -> -0.045940075 | F17: =CORREL(INDEX(DATA!$AG$3:$AK$3,$A$17):INDEX(DATA!$AG$1000:$AK$1000,$A$17),INDEX(DATA!$AG$3:$AK$3,F16):INDEX(DATA!$AG$1000:$AK$1000,F16)) -> 0.064760654 | T17: =DATA!AM17*$B$7 -> -48775.775
A18: 2 | B18: =CORREL(INDEX(DATA!$AG$3:$AK$3,$A$18):INDEX(DATA!$AG$1000:$AK$1000,$A$18),INDEX(DATA!$AG$3:$AK$3,B16):INDEX(DATA!$AG$1000:$AK$1000,B16)) -> -0.037573046 | C18: =CORREL(INDEX(DATA!$AG$3:$AK$3,$A$18):INDEX(DATA!$AG$1000:$AK$1000,$A$18),INDEX(DATA!$AG$3:$AK$3,C16):INDEX(DATA!$AG$1000:$AK$1000,C16)) -> 1 | D18: =CORREL(INDEX(DATA!$AG$3:$AK$3,$A$18):INDEX(DATA!$AG$1000:$AK$1000,$A$18),INDEX(DATA!$AG$3:$AK$3,D16):INDEX(DATA!$AG$1000:$AK$1000,D16)) -> 0.040449467 | E18: =CORREL(INDEX(DATA!$AG$3:$AK$3,$A$18):INDEX(DATA!$AG$1000:$AK$1000,$A$18),INDEX(DATA!$AG$3:$AK$3,E16):INDEX(DATA!$AG$1000:$AK$1000,E16)) -> -0.020701267 | F18: =CORREL(INDEX(DATA!$AG$3:$AK$3,$A$18):INDEX(DATA!$AG$1000:$AK$1000,$A$18),INDEX(DATA!$AG$3:$AK$3,F16):INDEX(DATA!$AG$1000:$AK$1000,F16)) -> -0.0097772967 | T18: =DATA!AM18*$B$7 -> 385423.4
A19: 3 | B19: =CORREL(INDEX(DATA!$AG$3:$AK$3,$A$19):INDEX(DATA!$AG$1000:$AK$1000,$A$19),INDEX(DATA!$AG$3:$AK$3,B16):INDEX(DATA!$AG$1000:$AK$1000,B16)) -> -0.021560812 | C19: =CORREL(INDEX(DATA!$AG$3:$AK$3,$A$19):INDEX(DATA!$AG$1000:$AK$1000,$A$19),INDEX(DATA!$AG$3:$AK$3,C16):INDEX(DATA!$AG$1000:$AK$1000,C16)) -> 0.040449467 | D19: =CORREL(INDEX(DATA!$AG$3:$AK$3,$A$19):INDEX(DATA!$AG$1000:$AK$1000,$A$19),INDEX(DATA!$AG$3:$AK$3,D16):INDEX(DATA!$AG$1000:$AK$1000,D16)) -> 1 | E19: =CORREL(INDEX(DATA!$AG$3:$AK$3,$A$19):INDEX(DATA!$AG$1000:$AK$1000,$A$19),INDEX(DATA!$AG$3:$AK$3,E16):INDEX(DATA!$AG$1000:$AK$1000,E16)) -> 0.018179643 | F19: =CORREL(INDEX(DATA!$AG$3:$AK$3,$A$19):INDEX(DATA!$AG$1000:$AK$1000,$A$19),INDEX(DATA!$AG$3:$AK$3,F16):INDEX(DATA!$AG$1000:$AK$1000,F16)) -> -0.042391209 | T19: =DATA!AM19*$B$7 -> -64100.321
A20: 4 | B20: =CORREL(INDEX(DATA!$AG$3:$AK$3,$A$20):INDEX(DATA!$AG$1000:$AK$1000,$A$20),INDEX(DATA!$AG$3:$AK$3,B16):INDEX(DATA!$AG$1000:$AK$1000,B16)) -> -0.045940075 | C20: =CORREL(INDEX(DATA!$AG$3:$AK$3,$A$20):INDEX(DATA!$AG$1000:$AK$1000,$A$20),INDEX(DATA!$AG$3:$AK$3,C16):INDEX(DATA!$AG$1000:$AK$1000,C16)) -> -0.020701267 | D20: =CORREL(INDEX(DATA!$AG$3:$AK$3,$A$20):INDEX(DATA!$AG$1000:$AK$1000,$A$20),INDEX(DATA!$AG$3:$AK$3,D16):INDEX(DATA!$AG$1000:$AK$1000,D16)) -> 0.018179643 | E20: =CORREL(INDEX(DATA!$AG$3:$AK$3,$A$20):INDEX(DATA!$AG$1000:$AK$1000,$A$20),INDEX(DATA!$AG$3:$AK$3,E16):INDEX(DATA!$AG$1000:$AK$1000,E16)) -> 1 | F20: =CORREL(INDEX(DATA!$AG$3:$AK$3,$A$20):INDEX(DATA!$AG$1000:$AK$1000,$A$20),INDEX(DATA!$AG$3:$AK$3,F16):INDEX(DATA!$AG$1000:$AK$1000,F16)) -> -0.054978162 | T20: =DATA!AM20*$B$7 -> -161692.52
A21: 5 | B21: =CORREL(INDEX(DATA!$AG$3:$AK$3,$A$21):INDEX(DATA!$AG$1000:$AK$1000,$A$21),INDEX(DATA!$AG$3:$AK$3,B16):INDEX(DATA!$AG$1000:$AK$1000,B16)) -> 0.064760654 | C21: =CORREL(INDEX(DATA!$AG$3:$AK$3,$A$21):INDEX(DATA!$AG$1000:$AK$1000,$A$21),INDEX(DATA!$AG$3:$AK$3,C16):INDEX(DATA!$AG$1000:$AK$1000,C16)) -> -0.0097772967 | D21: =CORREL(INDEX(DATA!$AG$3:$AK$3,$A$21):INDEX(DATA!$AG$1000:$AK$1000,$A$21),INDEX(DATA!$AG$3:$AK$3,D16):INDEX(DATA!$AG$1000:$AK$1000,D16)) -> -0.042391209 | E21: =CORREL(INDEX(DATA!$AG$3:$AK$3,$A$21):INDEX(DATA!$AG$1000:$AK$1000,$A$21),INDEX(DATA!$AG$3:$AK$3,E16):INDEX(DATA!$AG$1000:$AK$1000,E16)) -> -0.054978162 | F21: =CORREL(INDEX(DATA!$AG$3:$AK$3,$A$21):INDEX(DATA!$AG$1000:$AK$1000,$A$21),INDEX(DATA!$AG$3:$AK$3,F16):INDEX(DATA!$AG$1000:$AK$1000,F16)) -> 1 | T21: =DATA!AM21*$B$7 -> 91683.73
A22: Variance Covariance Matrix: | B22: 1 | C22: 2 | D22: 3 | E22: 4 | T22: =DATA!AM22*$B$7 -> 313065.73
A23: 1 | B23: =_xlfn.COVARIANCE.S(INDEX(DATA!$AG$3:$AJ$3,$A$23):INDEX(DATA!$AG$1000:$AJ$1000,$A$23),INDEX(DATA!$AG$3:$AJ$3,B22):INDEX(DATA!$AG$1000:$AJ$1000,B22)) -> 5.3558444e-08 | C23: =_xlfn.COVARIANCE.S(INDEX(DATA!$AG$3:$AJ$3,$A$23):INDEX(DATA!$AG$1000:$AJ$1000,$A$23),INDEX(DATA!$AG$3:$AJ$3,C22):INDEX(DATA!$AG$1000:$AJ$1000,C22)) -> -4.3562889e-09 | D23: =_xlfn.COVARIANCE.S(INDEX(DATA!$AG$3:$AJ$3,$A$23):INDEX(DATA!$AG$1000:$AJ$1000,$A$23),INDEX(DATA!$AG$3:$AJ$3,D22):INDEX(DATA!$AG$1000:$AJ$1000,D22)) -> -3.3679454e-09 | E23: =_xlfn.COVARIANCE.S(INDEX(DATA!$AG$3:$AJ$3,$A$23):INDEX(DATA!$AG$1000:$AJ$1000,$A$23),INDEX(DATA!$AG$3:$AJ$3,E22):INDEX(DATA!$AG$1000:$AJ$1000,E22)) -> -7.225353e-09 | T23: =DATA!AM23*$B$7 -> -60823.541
A24: 2 | B24: =_xlfn.COVARIANCE.S(INDEX(DATA!$AG$3:$AJ$3,$A$24):INDEX(DATA!$AG$1000:$AJ$1000,$A$24),INDEX(DATA!$AG$3:$AJ$3,B22):INDEX(DATA!$AG$1000:$AJ$1000,B22)) -> -4.3562889e-09 | C24: =_xlfn.COVARIANCE.S(INDEX(DATA!$AG$3:$AJ$3,$A$24):INDEX(DATA!$AG$1000:$AJ$1000,$A$24),INDEX(DATA!$AG$3:$AJ$3,C22):INDEX(DATA!$AG$1000:$AJ$1000,C22)) -> 2.5098778e-07 | D24: =_xlfn.COVARIANCE.S(INDEX(DATA!$AG$3:$AJ$3,$A$24):INDEX(DATA!$AG$1000:$AJ$1000,$A$24),INDEX(DATA!$AG$3:$AJ$3,D22):INDEX(DATA!$AG$1000:$AJ$1000,D22)) -> 1.3678077e-08 | E24: =_xlfn.COVARIANCE.S(INDEX(DATA!$AG$3:$AJ$3,$A$24):INDEX(DATA!$AG$1000:$AJ$1000,$A$24),INDEX(DATA!$AG$3:$AJ$3,E22):INDEX(DATA!$AG$1000:$AJ$1000,E22)) -> -7.0481739e-09 | T24: =DATA!AM24*$B$7 -> -259873.72
A25: 3 | B25: =_xlfn.COVARIANCE.S(INDEX(DATA!$AG$3:$AJ$3,$A$25):INDEX(DATA!$AG$1000:$AJ$1000,$A$25),INDEX(DATA!$AG$3:$AJ$3,B22):INDEX(DATA!$AG$1000:$AJ$1000,B22)) -> -3.3679454e-09 | C25: =_xlfn.COVARIANCE.S(INDEX(DATA!$AG$3:$AJ$3,$A$25):INDEX(DATA!$AG$1000:$AJ$1000,$A$25),INDEX(DATA!$AG$3:$AJ$3,C22):INDEX(DATA!$AG$1000:$AJ$1000,C22)) -> 1.3678077e-08 | D25: =_xlfn.COVARIANCE.S(INDEX(DATA!$AG$3:$AJ$3,$A$25):INDEX(DATA!$AG$1000:$AJ$1000,$A$25),INDEX(DATA!$AG$3:$AJ$3,D22):INDEX(DATA!$AG$1000:$AJ$1000,D22)) -> 4.5558758e-07 | E25: =_xlfn.COVARIANCE.S(INDEX(DATA!$AG$3:$AJ$3,$A$25):INDEX(DATA!$AG$1000:$AJ$1000,$A$25),INDEX(DATA!$AG$3:$AJ$3,E22):INDEX(DATA!$AG$1000:$AJ$1000,E22)) -> 8.3392059e-09 | T25: =DATA!AM25*$B$7 -> 1490.2301
A26: 4 | B26: =_xlfn.COVARIANCE.S(INDEX(DATA!$AG$3:$AJ$3,$A$26):INDEX(DATA!$AG$1000:$AJ$1000,$A$26),INDEX(DATA!$AG$3:$AJ$3,B22):INDEX(DATA!$AG$1000:$AJ$1000,B22)) -> -7.225353e-09 | C26: =_xlfn.COVARIANCE.S(INDEX(DATA!$AG$3:$AJ$3,$A$26):INDEX(DATA!$AG$1000:$AJ$1000,$A$26),INDEX(DATA!$AG$3:$AJ$3,C22):INDEX(DATA!$AG$1000:$AJ$1000,C22)) -> -7.0481739e-09 | D26: =_xlfn.COVARIANCE.S(INDEX(DATA!$AG$3:$AJ$3,$A$26):INDEX(DATA!$AG$1000:$AJ$1000,$A$26),INDEX(DATA!$AG$3:$AJ$3,D22):INDEX(DATA!$AG$1000:$AJ$1000,D22)) -> 8.3392059e-09 | E26: =_xlfn.COVARIANCE.S(INDEX(DATA!$AG$3:$AJ$3,$A$26):INDEX(DATA!$AG$1000:$AJ$1000,$A$26),INDEX(DATA!$AG$3:$AJ$3,E22):INDEX(DATA!$AG$1000:$AJ$1000,E22)) -> 4.6185621e-07 | T26: =DATA!AM26*$B$7 -> -115072.38
A27: Inverse of Variance Covariance Matrix: | T27: =DATA!AM27*$B$7 -> -91741.856
B28: {=MINVERSE(B23:E26)} -> 18745476 | C28: 326948.28 | D28: 123342.14 | E28: 296019.61 | O28: Efficient porfolio frontier | Q28: Capital market line | T28: =DATA!AM28*$B$7 -> 192678.81
B29: 326948.28 | C29: 3998328 | D29: -118874.35 | E29: 68277.843 | O29: Risk | P29: Return | Q29: risk | R29: return | T29: =DATA!AM29*$B$7 -> 117077.86
B30: 123342.14 | C30: -118874.35 | D30: 2200173.4 | E30: -39610.501 | O30: {=SQRT(($B$36*P30^2 - 2*$B$37*P30 +$B$38)/$B$39)} -> 0.0034078147 | P30: 0 | Q30: 0 | R30: =$B$8+$B$42*Q30 -> 0.25 | T30: =DATA!AM30*$B$7 -> 316183.26
B31: 296019.61 | C31: 68277.843 | D31: -39610.501 | E31: 2171564.2 | O31: =SQRT(($B$36*P31^2 - 2*$B$37*P31 +$B$38)/$B$39) -> 0.0033932959 | P31: =P30+0.1% -> 0.001 | Q31: =Q30+0.03 -> 0.03 | R31: =$B$8+$B$42*Q31 -> 0.10458248 | T31: =DATA!AM31*$B$7 -> -333691.21
A32: e-vector | B32: 1 | C32: 1 | D32: 1 | E32: 1 | O32: =SQRT(($B$36*P32^2 - 2*$B$37*P32 +$B$38)/$B$39) -> 0.0033787772 | P32: =P31+0.1% -> 0.002 | Q32: =Q31+0.03 -> 0.06 | R32: =$B$8+$B$42*Q32 -> -0.040835042 | T32: =DATA!AM32*$B$7 -> -66105.608
A33: r-vector | B33: =I12 -> 0.22471802 | C33: =I13 -> 0.25176321 | D33: =I14 -> 0.25567424 | E33: =I15 -> 0.25730892 | O33: =SQRT(($B$36*P33^2 - 2*$B$37*P33 +$B$38)/$B$39) -> 0.0033642588 | P33: =P32+0.1% -> 0.003 | Q33: =Q32+0.03 -> 0.09 | R33: =$B$8+$B$42*Q33 -> -0.18625256 | T33: =DATA!AM33*$B$7 -> 314094.55
A34: h-vector | B34: {=MMULT(B32:E32,B28:E31)} -> 19491786 | C34: 4274679.8 | D34: 2165030.7 | E34: 2496251.1 | O34: =SQRT(($B$36*P34^2 - 2*$B$37*P34 +$B$38)/$B$39) -> 0.0033497405 | P34: =P33+0.1% -> 0.004 | Q34: =Q33+0.03 -> 0.12 | R34: =$B$8+$B$42*Q34 -> -0.33167008 | T34: =DATA!AM34*$B$7 -> -173640.11
A35: g-vector | B35: {=MMULT(B33:E33,B28:E31)} -> 4402463.7 | C35: 1067278.4 | D35: 550124.54 | E35: 632346.24 | O35: =SQRT(($B$36*P35^2 - 2*$B$37*P35 +$B$38)/$B$39) -> 0.0033352224 | P35: =P34+0.1% -> 0.005 | Q35: =Q34+0.03 -> 0.15 | R35: =$B$8+$B$42*Q35 -> -0.4770876 | T35: =DATA!AM35*$B$7 -> -210151.28
A36: alpha | B36: {=MMULT(B32:E32,TRANSPOSE(B34:E34))} -> 28427748 | O36: =SQRT(($B$36*P36^2 - 2*$B$37*P36 +$B$38)/$B$39) -> 0.0033207046 | P36: =P35+0.1% -> 0.006 | Q36: =Q35+0.03 -> 0.18 | R36: =$B$8+$B$42*Q36 -> -0.62250512 | T36: =DATA!AM36*$B$7 -> 5857.0123
A37: beta | B37: {=MMULT(B32:E32,TRANSPOSE(B35:E35))} -> 6652212.9 | O37: =SQRT(($B$36*P37^2 - 2*$B$37*P37 +$B$38)/$B$39) -> 0.0033061869 | P37: =P36+0.1% -> 0.007 | Q37: =Q36+0.03 -> 0.21 | R37: =$B$8+$B$42*Q37 -> -0.76792265 | T37: =DATA!AM37*$B$7 -> 139061.3
A38: gamma | B38: {=MMULT(B33:E33,TRANSPOSE(B35:E35))} -> 1561375.4 | O38: =SQRT(($B$36*P38^2 - 2*$B$37*P38 +$B$38)/$B$39) -> 0.0032916694 | P38: =P37+0.1% -> 0.008 | Q38: =Q37+0.03 -> 0.24 | R38: =$B$8+$B$42*Q38 -> -0.91334017 | T38: =DATA!AM38*$B$7 -> 243738.55
A39: delta | B39: =B36*B38-B37^2 -> 1.3444832e+11 | O39: =SQRT(($B$36*P39^2 - 2*$B$37*P39 +$B$38)/$B$39) -> 0.0032771522 | P39: =P38+0.1% -> 0.009 | Q39: =Q38+0.03 -> 0.27 | R39: =$B$8+$B$42*Q39 -> -1.0587577 | T39: =DATA!AM39*$B$7 -> -8423.9278
A40: tangency return | B40: =(B38 - B37*B2)/(B37-B36*B2) -> 0.24862573 | O40: =SQRT(($B$36*P40^2 - 2*$B$37*P40 +$B$38)/$B$39) -> 0.0032626352 | P40: =P39+0.1% -> 0.01 | Q40: =Q39+0.03 -> 0.3 | R40: =$B$8+$B$42*Q40 -> -1.2041752
...
